INFO - 2024-11-11 16:59:10,095 - process: 8332 - scheduler.py - gerapy.server.core.scheduler - 105 - scheduler - successfully synced task with jobs with force
ERROR - 2024-11-11 16:59:14,942 - process: 8332 - utils.py - gerapy.server.core.utils - 564 - utils - [WinError 3] 系统找不到指定的路径。: 'C:\\robot_work\\projects'
Traceback (most recent call last):
  File "C:\robot_work\.venv\Lib\site-packages\gerapy\server\core\utils.py", line 562, in wrapper
    result = func(*args, **kwargs)
             ^^^^^^^^^^^^^^^^^^^^^
  File "C:\robot_work\.venv\Lib\site-packages\django\views\decorators\csrf.py", line 54, in wrapped_view
    return view_func(*args, **kwargs)
           ^^^^^^^^^^^^^^^^^^^^^^^^^^
  File "C:\robot_work\.venv\Lib\site-packages\django\views\generic\base.py", line 71, in view
    return self.dispatch(request, *args, **kwargs)
           ^^^^^^^^^^^^^^^^^^^^^^^^^^^^^^^^^^^^^^^
  File "C:\robot_work\.venv\Lib\site-packages\rest_framework\views.py", line 509, in dispatch
    response = self.handle_exception(exc)
               ^^^^^^^^^^^^^^^^^^^^^^^^^^
  File "C:\robot_work\.venv\Lib\site-packages\rest_framework\views.py", line 469, in handle_exception
    self.raise_uncaught_exception(exc)
  File "C:\robot_work\.venv\Lib\site-packages\rest_framework\views.py", line 480, in raise_uncaught_exception
    raise exc
  File "C:\robot_work\.venv\Lib\site-packages\rest_framework\views.py", line 506, in dispatch
    response = handler(request, *args, **kwargs)
               ^^^^^^^^^^^^^^^^^^^^^^^^^^^^^^^^^
  File "C:\robot_work\.venv\Lib\site-packages\rest_framework\decorators.py", line 50, in handler
    return func(*args, **kwargs)
           ^^^^^^^^^^^^^^^^^^^^^
  File "C:\robot_work\.venv\Lib\site-packages\gerapy\server\core\views.py", line 73, in index_status
    files = os.listdir(path)
            ^^^^^^^^^^^^^^^^
FileNotFoundError: [WinError 3] 系统找不到指定的路径。: 'C:\\robot_work\\projects'
ERROR - 2024-11-11 16:59:19,410 - process: 8332 - utils.py - gerapy.server.core.utils - 564 - utils - HTTPConnectionPool(host='10.34.4.139', port=6800): Max retries exceeded with url: / (Caused by ConnectTimeoutError(<urllib3.connection.HTTPConnection object at 0x0000016953BB28D0>, 'Connection to 10.34.4.139 timed out. (connect timeout=3)'))
Traceback (most recent call last):
  File "C:\robot_work\.venv\Lib\site-packages\urllib3\connection.py", line 174, in _new_conn
    conn = connection.create_connection(
           ^^^^^^^^^^^^^^^^^^^^^^^^^^^^^
  File "C:\robot_work\.venv\Lib\site-packages\urllib3\util\connection.py", line 95, in create_connection
    raise err
  File "C:\robot_work\.venv\Lib\site-packages\urllib3\util\connection.py", line 85, in create_connection
    sock.connect(sa)
TimeoutError: timed out

During handling of the above exception, another exception occurred:

Traceback (most recent call last):
  File "C:\robot_work\.venv\Lib\site-packages\urllib3\connectionpool.py", line 716, in urlopen
    httplib_response = self._make_request(
                       ^^^^^^^^^^^^^^^^^^^
  File "C:\robot_work\.venv\Lib\site-packages\urllib3\connectionpool.py", line 416, in _make_request
    conn.request(method, url, **httplib_request_kw)
  File "C:\robot_work\.venv\Lib\site-packages\urllib3\connection.py", line 244, in request
    super(HTTPConnection, self).request(method, url, body=body, headers=headers)
  File "C:\Users\张洛\AppData\Local\Programs\Python\Python312\Lib\http\client.py", line 1319, in request
    self._send_request(method, url, body, headers, encode_chunked)
  File "C:\Users\张洛\AppData\Local\Programs\Python\Python312\Lib\http\client.py", line 1365, in _send_request
    self.endheaders(body, encode_chunked=encode_chunked)
  File "C:\Users\张洛\AppData\Local\Programs\Python\Python312\Lib\http\client.py", line 1314, in endheaders
    self._send_output(message_body, encode_chunked=encode_chunked)
  File "C:\Users\张洛\AppData\Local\Programs\Python\Python312\Lib\http\client.py", line 1074, in _send_output
    self.send(msg)
  File "C:\Users\张洛\AppData\Local\Programs\Python\Python312\Lib\http\client.py", line 1018, in send
    self.connect()
  File "C:\robot_work\.venv\Lib\site-packages\urllib3\connection.py", line 205, in connect
    conn = self._new_conn()
           ^^^^^^^^^^^^^^^^
  File "C:\robot_work\.venv\Lib\site-packages\urllib3\connection.py", line 179, in _new_conn
    raise ConnectTimeoutError(
urllib3.exceptions.ConnectTimeoutError: (<urllib3.connection.HTTPConnection object at 0x0000016953BB28D0>, 'Connection to 10.34.4.139 timed out. (connect timeout=3)')

During handling of the above exception, another exception occurred:

Traceback (most recent call last):
  File "C:\robot_work\.venv\Lib\site-packages\requests\adapters.py", line 667, in send
    resp = conn.urlopen(
           ^^^^^^^^^^^^^
  File "C:\robot_work\.venv\Lib\site-packages\urllib3\connectionpool.py", line 802, in urlopen
    retries = retries.increment(
              ^^^^^^^^^^^^^^^^^^
  File "C:\robot_work\.venv\Lib\site-packages\urllib3\util\retry.py", line 594, in increment
    raise MaxRetryError(_pool, url, error or ResponseError(cause))
urllib3.exceptions.MaxRetryError: HTTPConnectionPool(host='10.34.4.139', port=6800): Max retries exceeded with url: / (Caused by ConnectTimeoutError(<urllib3.connection.HTTPConnection object at 0x0000016953BB28D0>, 'Connection to 10.34.4.139 timed out. (connect timeout=3)'))

During handling of the above exception, another exception occurred:

Traceback (most recent call last):
  File "C:\robot_work\.venv\Lib\site-packages\gerapy\server\core\utils.py", line 562, in wrapper
    result = func(*args, **kwargs)
             ^^^^^^^^^^^^^^^^^^^^^
  File "C:\robot_work\.venv\Lib\site-packages\django\views\decorators\csrf.py", line 54, in wrapped_view
    return view_func(*args, **kwargs)
           ^^^^^^^^^^^^^^^^^^^^^^^^^^
  File "C:\robot_work\.venv\Lib\site-packages\django\views\generic\base.py", line 71, in view
    return self.dispatch(request, *args, **kwargs)
           ^^^^^^^^^^^^^^^^^^^^^^^^^^^^^^^^^^^^^^^
  File "C:\robot_work\.venv\Lib\site-packages\rest_framework\views.py", line 509, in dispatch
    response = self.handle_exception(exc)
               ^^^^^^^^^^^^^^^^^^^^^^^^^^
  File "C:\robot_work\.venv\Lib\site-packages\rest_framework\views.py", line 469, in handle_exception
    self.raise_uncaught_exception(exc)
  File "C:\robot_work\.venv\Lib\site-packages\rest_framework\views.py", line 480, in raise_uncaught_exception
    raise exc
  File "C:\robot_work\.venv\Lib\site-packages\rest_framework\views.py", line 506, in dispatch
    response = handler(request, *args, **kwargs)
               ^^^^^^^^^^^^^^^^^^^^^^^^^^^^^^^^^
  File "C:\robot_work\.venv\Lib\site-packages\rest_framework\decorators.py", line 50, in handler
    return func(*args, **kwargs)
           ^^^^^^^^^^^^^^^^^^^^^
  File "C:\robot_work\.venv\Lib\site-packages\gerapy\server\core\views.py", line 120, in client_status
    requests.get(scrapyd_url(client.ip, client.port), timeout=3)
  File "C:\robot_work\.venv\Lib\site-packages\requests\api.py", line 73, in get
    return request("get", url, params=params, **kwargs)
           ^^^^^^^^^^^^^^^^^^^^^^^^^^^^^^^^^^^^^^^^^^^^
  File "C:\robot_work\.venv\Lib\site-packages\requests\api.py", line 59, in request
    return session.request(method=method, url=url, **kwargs)
           ^^^^^^^^^^^^^^^^^^^^^^^^^^^^^^^^^^^^^^^^^^^^^^^^^
  File "C:\robot_work\.venv\Lib\site-packages\requests\sessions.py", line 589, in request
    resp = self.send(prep, **send_kwargs)
           ^^^^^^^^^^^^^^^^^^^^^^^^^^^^^^
  File "C:\robot_work\.venv\Lib\site-packages\requests\sessions.py", line 703, in send
    r = adapter.send(request, **kwargs)
        ^^^^^^^^^^^^^^^^^^^^^^^^^^^^^^^
  File "C:\robot_work\.venv\Lib\site-packages\requests\adapters.py", line 688, in send
    raise ConnectTimeout(e, request=request)
requests.exceptions.ConnectTimeout: HTTPConnectionPool(host='10.34.4.139', port=6800): Max retries exceeded with url: / (Caused by ConnectTimeoutError(<urllib3.connection.HTTPConnection object at 0x0000016953BB28D0>, 'Connection to 10.34.4.139 timed out. (connect timeout=3)'))
ERROR - 2024-11-11 16:59:20,446 - process: 8332 - utils.py - gerapy.server.core.utils - 564 - utils - HTTPConnectionPool(host='localhost', port=6800): Max retries exceeded with url: / (Caused by NewConnectionError('<urllib3.connection.HTTPConnection object at 0x0000016953BB2F90>: Failed to establish a new connection: [WinError 10061] 由于目标计算机积极拒绝，无法连接。'))
Traceback (most recent call last):
  File "C:\robot_work\.venv\Lib\site-packages\urllib3\connection.py", line 174, in _new_conn
    conn = connection.create_connection(
           ^^^^^^^^^^^^^^^^^^^^^^^^^^^^^
  File "C:\robot_work\.venv\Lib\site-packages\urllib3\util\connection.py", line 95, in create_connection
    raise err
  File "C:\robot_work\.venv\Lib\site-packages\urllib3\util\connection.py", line 85, in create_connection
    sock.connect(sa)
ConnectionRefusedError: [WinError 10061] 由于目标计算机积极拒绝，无法连接。

During handling of the above exception, another exception occurred:

Traceback (most recent call last):
  File "C:\robot_work\.venv\Lib\site-packages\urllib3\connectionpool.py", line 716, in urlopen
    httplib_response = self._make_request(
                       ^^^^^^^^^^^^^^^^^^^
  File "C:\robot_work\.venv\Lib\site-packages\urllib3\connectionpool.py", line 416, in _make_request
    conn.request(method, url, **httplib_request_kw)
  File "C:\robot_work\.venv\Lib\site-packages\urllib3\connection.py", line 244, in request
    super(HTTPConnection, self).request(method, url, body=body, headers=headers)
  File "C:\Users\张洛\AppData\Local\Programs\Python\Python312\Lib\http\client.py", line 1319, in request
    self._send_request(method, url, body, headers, encode_chunked)
  File "C:\Users\张洛\AppData\Local\Programs\Python\Python312\Lib\http\client.py", line 1365, in _send_request
    self.endheaders(body, encode_chunked=encode_chunked)
  File "C:\Users\张洛\AppData\Local\Programs\Python\Python312\Lib\http\client.py", line 1314, in endheaders
    self._send_output(message_body, encode_chunked=encode_chunked)
  File "C:\Users\张洛\AppData\Local\Programs\Python\Python312\Lib\http\client.py", line 1074, in _send_output
    self.send(msg)
  File "C:\Users\张洛\AppData\Local\Programs\Python\Python312\Lib\http\client.py", line 1018, in send
    self.connect()
  File "C:\robot_work\.venv\Lib\site-packages\urllib3\connection.py", line 205, in connect
    conn = self._new_conn()
           ^^^^^^^^^^^^^^^^
  File "C:\robot_work\.venv\Lib\site-packages\urllib3\connection.py", line 186, in _new_conn
    raise NewConnectionError(
urllib3.exceptions.NewConnectionError: <urllib3.connection.HTTPConnection object at 0x0000016953BB2F90>: Failed to establish a new connection: [WinError 10061] 由于目标计算机积极拒绝，无法连接。

During handling of the above exception, another exception occurred:

Traceback (most recent call last):
  File "C:\robot_work\.venv\Lib\site-packages\requests\adapters.py", line 667, in send
    resp = conn.urlopen(
           ^^^^^^^^^^^^^
  File "C:\robot_work\.venv\Lib\site-packages\urllib3\connectionpool.py", line 802, in urlopen
    retries = retries.increment(
              ^^^^^^^^^^^^^^^^^^
  File "C:\robot_work\.venv\Lib\site-packages\urllib3\util\retry.py", line 594, in increment
    raise MaxRetryError(_pool, url, error or ResponseError(cause))
urllib3.exceptions.MaxRetryError: HTTPConnectionPool(host='localhost', port=6800): Max retries exceeded with url: / (Caused by NewConnectionError('<urllib3.connection.HTTPConnection object at 0x0000016953BB2F90>: Failed to establish a new connection: [WinError 10061] 由于目标计算机积极拒绝，无法连接。'))

During handling of the above exception, another exception occurred:

Traceback (most recent call last):
  File "C:\robot_work\.venv\Lib\site-packages\gerapy\server\core\utils.py", line 562, in wrapper
    result = func(*args, **kwargs)
             ^^^^^^^^^^^^^^^^^^^^^
  File "C:\robot_work\.venv\Lib\site-packages\django\views\decorators\csrf.py", line 54, in wrapped_view
    return view_func(*args, **kwargs)
           ^^^^^^^^^^^^^^^^^^^^^^^^^^
  File "C:\robot_work\.venv\Lib\site-packages\django\views\generic\base.py", line 71, in view
    return self.dispatch(request, *args, **kwargs)
           ^^^^^^^^^^^^^^^^^^^^^^^^^^^^^^^^^^^^^^^
  File "C:\robot_work\.venv\Lib\site-packages\rest_framework\views.py", line 509, in dispatch
    response = self.handle_exception(exc)
               ^^^^^^^^^^^^^^^^^^^^^^^^^^
  File "C:\robot_work\.venv\Lib\site-packages\rest_framework\views.py", line 469, in handle_exception
    self.raise_uncaught_exception(exc)
  File "C:\robot_work\.venv\Lib\site-packages\rest_framework\views.py", line 480, in raise_uncaught_exception
    raise exc
  File "C:\robot_work\.venv\Lib\site-packages\rest_framework\views.py", line 506, in dispatch
    response = handler(request, *args, **kwargs)
               ^^^^^^^^^^^^^^^^^^^^^^^^^^^^^^^^^
  File "C:\robot_work\.venv\Lib\site-packages\rest_framework\decorators.py", line 50, in handler
    return func(*args, **kwargs)
           ^^^^^^^^^^^^^^^^^^^^^
  File "C:\robot_work\.venv\Lib\site-packages\gerapy\server\core\views.py", line 120, in client_status
    requests.get(scrapyd_url(client.ip, client.port), timeout=3)
  File "C:\robot_work\.venv\Lib\site-packages\requests\api.py", line 73, in get
    return request("get", url, params=params, **kwargs)
           ^^^^^^^^^^^^^^^^^^^^^^^^^^^^^^^^^^^^^^^^^^^^
  File "C:\robot_work\.venv\Lib\site-packages\requests\api.py", line 59, in request
    return session.request(method=method, url=url, **kwargs)
           ^^^^^^^^^^^^^^^^^^^^^^^^^^^^^^^^^^^^^^^^^^^^^^^^^
  File "C:\robot_work\.venv\Lib\site-packages\requests\sessions.py", line 589, in request
    resp = self.send(prep, **send_kwargs)
           ^^^^^^^^^^^^^^^^^^^^^^^^^^^^^^
  File "C:\robot_work\.venv\Lib\site-packages\requests\sessions.py", line 703, in send
    r = adapter.send(request, **kwargs)
        ^^^^^^^^^^^^^^^^^^^^^^^^^^^^^^^
  File "C:\robot_work\.venv\Lib\site-packages\requests\adapters.py", line 700, in send
    raise ConnectionError(e, request=request)
requests.exceptions.ConnectionError: HTTPConnectionPool(host='localhost', port=6800): Max retries exceeded with url: / (Caused by NewConnectionError('<urllib3.connection.HTTPConnection object at 0x0000016953BB2F90>: Failed to establish a new connection: [WinError 10061] 由于目标计算机积极拒绝，无法连接。'))
ERROR - 2024-11-11 17:00:38,188 - process: 8332 - utils.py - gerapy.server.core.utils - 564 - utils - HTTPConnectionPool(host='localhost', port=6800): Max retries exceeded with url: / (Caused by NewConnectionError('<urllib3.connection.HTTPConnection object at 0x0000016953A0A210>: Failed to establish a new connection: [WinError 10061] 由于目标计算机积极拒绝，无法连接。'))
Traceback (most recent call last):
  File "C:\robot_work\.venv\Lib\site-packages\urllib3\connection.py", line 174, in _new_conn
    conn = connection.create_connection(
           ^^^^^^^^^^^^^^^^^^^^^^^^^^^^^
  File "C:\robot_work\.venv\Lib\site-packages\urllib3\util\connection.py", line 95, in create_connection
    raise err
  File "C:\robot_work\.venv\Lib\site-packages\urllib3\util\connection.py", line 85, in create_connection
    sock.connect(sa)
ConnectionRefusedError: [WinError 10061] 由于目标计算机积极拒绝，无法连接。

During handling of the above exception, another exception occurred:

Traceback (most recent call last):
  File "C:\robot_work\.venv\Lib\site-packages\urllib3\connectionpool.py", line 716, in urlopen
    httplib_response = self._make_request(
                       ^^^^^^^^^^^^^^^^^^^
  File "C:\robot_work\.venv\Lib\site-packages\urllib3\connectionpool.py", line 416, in _make_request
    conn.request(method, url, **httplib_request_kw)
  File "C:\robot_work\.venv\Lib\site-packages\urllib3\connection.py", line 244, in request
    super(HTTPConnection, self).request(method, url, body=body, headers=headers)
  File "C:\Users\张洛\AppData\Local\Programs\Python\Python312\Lib\http\client.py", line 1319, in request
    self._send_request(method, url, body, headers, encode_chunked)
  File "C:\Users\张洛\AppData\Local\Programs\Python\Python312\Lib\http\client.py", line 1365, in _send_request
    self.endheaders(body, encode_chunked=encode_chunked)
  File "C:\Users\张洛\AppData\Local\Programs\Python\Python312\Lib\http\client.py", line 1314, in endheaders
    self._send_output(message_body, encode_chunked=encode_chunked)
  File "C:\Users\张洛\AppData\Local\Programs\Python\Python312\Lib\http\client.py", line 1074, in _send_output
    self.send(msg)
  File "C:\Users\张洛\AppData\Local\Programs\Python\Python312\Lib\http\client.py", line 1018, in send
    self.connect()
  File "C:\robot_work\.venv\Lib\site-packages\urllib3\connection.py", line 205, in connect
    conn = self._new_conn()
           ^^^^^^^^^^^^^^^^
  File "C:\robot_work\.venv\Lib\site-packages\urllib3\connection.py", line 186, in _new_conn
    raise NewConnectionError(
urllib3.exceptions.NewConnectionError: <urllib3.connection.HTTPConnection object at 0x0000016953A0A210>: Failed to establish a new connection: [WinError 10061] 由于目标计算机积极拒绝，无法连接。

During handling of the above exception, another exception occurred:

Traceback (most recent call last):
  File "C:\robot_work\.venv\Lib\site-packages\requests\adapters.py", line 667, in send
    resp = conn.urlopen(
           ^^^^^^^^^^^^^
  File "C:\robot_work\.venv\Lib\site-packages\urllib3\connectionpool.py", line 802, in urlopen
    retries = retries.increment(
              ^^^^^^^^^^^^^^^^^^
  File "C:\robot_work\.venv\Lib\site-packages\urllib3\util\retry.py", line 594, in increment
    raise MaxRetryError(_pool, url, error or ResponseError(cause))
urllib3.exceptions.MaxRetryError: HTTPConnectionPool(host='localhost', port=6800): Max retries exceeded with url: / (Caused by NewConnectionError('<urllib3.connection.HTTPConnection object at 0x0000016953A0A210>: Failed to establish a new connection: [WinError 10061] 由于目标计算机积极拒绝，无法连接。'))

During handling of the above exception, another exception occurred:

Traceback (most recent call last):
  File "C:\robot_work\.venv\Lib\site-packages\gerapy\server\core\utils.py", line 562, in wrapper
    result = func(*args, **kwargs)
             ^^^^^^^^^^^^^^^^^^^^^
  File "C:\robot_work\.venv\Lib\site-packages\django\views\decorators\csrf.py", line 54, in wrapped_view
    return view_func(*args, **kwargs)
           ^^^^^^^^^^^^^^^^^^^^^^^^^^
  File "C:\robot_work\.venv\Lib\site-packages\django\views\generic\base.py", line 71, in view
    return self.dispatch(request, *args, **kwargs)
           ^^^^^^^^^^^^^^^^^^^^^^^^^^^^^^^^^^^^^^^
  File "C:\robot_work\.venv\Lib\site-packages\rest_framework\views.py", line 509, in dispatch
    response = self.handle_exception(exc)
               ^^^^^^^^^^^^^^^^^^^^^^^^^^
  File "C:\robot_work\.venv\Lib\site-packages\rest_framework\views.py", line 469, in handle_exception
    self.raise_uncaught_exception(exc)
  File "C:\robot_work\.venv\Lib\site-packages\rest_framework\views.py", line 480, in raise_uncaught_exception
    raise exc
  File "C:\robot_work\.venv\Lib\site-packages\rest_framework\views.py", line 506, in dispatch
    response = handler(request, *args, **kwargs)
               ^^^^^^^^^^^^^^^^^^^^^^^^^^^^^^^^^
  File "C:\robot_work\.venv\Lib\site-packages\rest_framework\decorators.py", line 50, in handler
    return func(*args, **kwargs)
           ^^^^^^^^^^^^^^^^^^^^^
  File "C:\robot_work\.venv\Lib\site-packages\gerapy\server\core\views.py", line 120, in client_status
    requests.get(scrapyd_url(client.ip, client.port), timeout=3)
  File "C:\robot_work\.venv\Lib\site-packages\requests\api.py", line 73, in get
    return request("get", url, params=params, **kwargs)
           ^^^^^^^^^^^^^^^^^^^^^^^^^^^^^^^^^^^^^^^^^^^^
  File "C:\robot_work\.venv\Lib\site-packages\requests\api.py", line 59, in request
    return session.request(method=method, url=url, **kwargs)
           ^^^^^^^^^^^^^^^^^^^^^^^^^^^^^^^^^^^^^^^^^^^^^^^^^
  File "C:\robot_work\.venv\Lib\site-packages\requests\sessions.py", line 589, in request
    resp = self.send(prep, **send_kwargs)
           ^^^^^^^^^^^^^^^^^^^^^^^^^^^^^^
  File "C:\robot_work\.venv\Lib\site-packages\requests\sessions.py", line 703, in send
    r = adapter.send(request, **kwargs)
        ^^^^^^^^^^^^^^^^^^^^^^^^^^^^^^^
  File "C:\robot_work\.venv\Lib\site-packages\requests\adapters.py", line 700, in send
    raise ConnectionError(e, request=request)
requests.exceptions.ConnectionError: HTTPConnectionPool(host='localhost', port=6800): Max retries exceeded with url: / (Caused by NewConnectionError('<urllib3.connection.HTTPConnection object at 0x0000016953A0A210>: Failed to establish a new connection: [WinError 10061] 由于目标计算机积极拒绝，无法连接。'))
ERROR - 2024-11-11 17:01:25,357 - process: 8332 - utils.py - gerapy.server.core.utils - 564 - utils - HTTPConnectionPool(host='localhost', port=6800): Max retries exceeded with url: / (Caused by NewConnectionError('<urllib3.connection.HTTPConnection object at 0x0000016953C6E1B0>: Failed to establish a new connection: [WinError 10061] 由于目标计算机积极拒绝，无法连接。'))
Traceback (most recent call last):
  File "C:\robot_work\.venv\Lib\site-packages\urllib3\connection.py", line 174, in _new_conn
    conn = connection.create_connection(
           ^^^^^^^^^^^^^^^^^^^^^^^^^^^^^
  File "C:\robot_work\.venv\Lib\site-packages\urllib3\util\connection.py", line 95, in create_connection
    raise err
  File "C:\robot_work\.venv\Lib\site-packages\urllib3\util\connection.py", line 85, in create_connection
    sock.connect(sa)
ConnectionRefusedError: [WinError 10061] 由于目标计算机积极拒绝，无法连接。

During handling of the above exception, another exception occurred:

Traceback (most recent call last):
  File "C:\robot_work\.venv\Lib\site-packages\urllib3\connectionpool.py", line 716, in urlopen
    httplib_response = self._make_request(
                       ^^^^^^^^^^^^^^^^^^^
  File "C:\robot_work\.venv\Lib\site-packages\urllib3\connectionpool.py", line 416, in _make_request
    conn.request(method, url, **httplib_request_kw)
  File "C:\robot_work\.venv\Lib\site-packages\urllib3\connection.py", line 244, in request
    super(HTTPConnection, self).request(method, url, body=body, headers=headers)
  File "C:\Users\张洛\AppData\Local\Programs\Python\Python312\Lib\http\client.py", line 1319, in request
    self._send_request(method, url, body, headers, encode_chunked)
  File "C:\Users\张洛\AppData\Local\Programs\Python\Python312\Lib\http\client.py", line 1365, in _send_request
    self.endheaders(body, encode_chunked=encode_chunked)
  File "C:\Users\张洛\AppData\Local\Programs\Python\Python312\Lib\http\client.py", line 1314, in endheaders
    self._send_output(message_body, encode_chunked=encode_chunked)
  File "C:\Users\张洛\AppData\Local\Programs\Python\Python312\Lib\http\client.py", line 1074, in _send_output
    self.send(msg)
  File "C:\Users\张洛\AppData\Local\Programs\Python\Python312\Lib\http\client.py", line 1018, in send
    self.connect()
  File "C:\robot_work\.venv\Lib\site-packages\urllib3\connection.py", line 205, in connect
    conn = self._new_conn()
           ^^^^^^^^^^^^^^^^
  File "C:\robot_work\.venv\Lib\site-packages\urllib3\connection.py", line 186, in _new_conn
    raise NewConnectionError(
urllib3.exceptions.NewConnectionError: <urllib3.connection.HTTPConnection object at 0x0000016953C6E1B0>: Failed to establish a new connection: [WinError 10061] 由于目标计算机积极拒绝，无法连接。

During handling of the above exception, another exception occurred:

Traceback (most recent call last):
  File "C:\robot_work\.venv\Lib\site-packages\requests\adapters.py", line 667, in send
    resp = conn.urlopen(
           ^^^^^^^^^^^^^
  File "C:\robot_work\.venv\Lib\site-packages\urllib3\connectionpool.py", line 802, in urlopen
    retries = retries.increment(
              ^^^^^^^^^^^^^^^^^^
  File "C:\robot_work\.venv\Lib\site-packages\urllib3\util\retry.py", line 594, in increment
    raise MaxRetryError(_pool, url, error or ResponseError(cause))
urllib3.exceptions.MaxRetryError: HTTPConnectionPool(host='localhost', port=6800): Max retries exceeded with url: / (Caused by NewConnectionError('<urllib3.connection.HTTPConnection object at 0x0000016953C6E1B0>: Failed to establish a new connection: [WinError 10061] 由于目标计算机积极拒绝，无法连接。'))

During handling of the above exception, another exception occurred:

Traceback (most recent call last):
  File "C:\robot_work\.venv\Lib\site-packages\gerapy\server\core\utils.py", line 562, in wrapper
    result = func(*args, **kwargs)
             ^^^^^^^^^^^^^^^^^^^^^
  File "C:\robot_work\.venv\Lib\site-packages\django\views\decorators\csrf.py", line 54, in wrapped_view
    return view_func(*args, **kwargs)
           ^^^^^^^^^^^^^^^^^^^^^^^^^^
  File "C:\robot_work\.venv\Lib\site-packages\django\views\generic\base.py", line 71, in view
    return self.dispatch(request, *args, **kwargs)
           ^^^^^^^^^^^^^^^^^^^^^^^^^^^^^^^^^^^^^^^
  File "C:\robot_work\.venv\Lib\site-packages\rest_framework\views.py", line 509, in dispatch
    response = self.handle_exception(exc)
               ^^^^^^^^^^^^^^^^^^^^^^^^^^
  File "C:\robot_work\.venv\Lib\site-packages\rest_framework\views.py", line 469, in handle_exception
    self.raise_uncaught_exception(exc)
  File "C:\robot_work\.venv\Lib\site-packages\rest_framework\views.py", line 480, in raise_uncaught_exception
    raise exc
  File "C:\robot_work\.venv\Lib\site-packages\rest_framework\views.py", line 506, in dispatch
    response = handler(request, *args, **kwargs)
               ^^^^^^^^^^^^^^^^^^^^^^^^^^^^^^^^^
  File "C:\robot_work\.venv\Lib\site-packages\rest_framework\decorators.py", line 50, in handler
    return func(*args, **kwargs)
           ^^^^^^^^^^^^^^^^^^^^^
  File "C:\robot_work\.venv\Lib\site-packages\gerapy\server\core\views.py", line 120, in client_status
    requests.get(scrapyd_url(client.ip, client.port), timeout=3)
  File "C:\robot_work\.venv\Lib\site-packages\requests\api.py", line 73, in get
    return request("get", url, params=params, **kwargs)
           ^^^^^^^^^^^^^^^^^^^^^^^^^^^^^^^^^^^^^^^^^^^^
  File "C:\robot_work\.venv\Lib\site-packages\requests\api.py", line 59, in request
    return session.request(method=method, url=url, **kwargs)
           ^^^^^^^^^^^^^^^^^^^^^^^^^^^^^^^^^^^^^^^^^^^^^^^^^
  File "C:\robot_work\.venv\Lib\site-packages\requests\sessions.py", line 589, in request
    resp = self.send(prep, **send_kwargs)
           ^^^^^^^^^^^^^^^^^^^^^^^^^^^^^^
  File "C:\robot_work\.venv\Lib\site-packages\requests\sessions.py", line 703, in send
    r = adapter.send(request, **kwargs)
        ^^^^^^^^^^^^^^^^^^^^^^^^^^^^^^^
  File "C:\robot_work\.venv\Lib\site-packages\requests\adapters.py", line 700, in send
    raise ConnectionError(e, request=request)
requests.exceptions.ConnectionError: HTTPConnectionPool(host='localhost', port=6800): Max retries exceeded with url: / (Caused by NewConnectionError('<urllib3.connection.HTTPConnection object at 0x0000016953C6E1B0>: Failed to establish a new connection: [WinError 10061] 由于目标计算机积极拒绝，无法连接。'))
ERROR - 2024-11-11 17:03:16,145 - process: 8332 - utils.py - gerapy.server.core.utils - 564 - utils - HTTPConnectionPool(host='localhost', port=6800): Max retries exceeded with url: / (Caused by NewConnectionError('<urllib3.connection.HTTPConnection object at 0x0000016953C6D010>: Failed to establish a new connection: [WinError 10061] 由于目标计算机积极拒绝，无法连接。'))
Traceback (most recent call last):
  File "C:\robot_work\.venv\Lib\site-packages\urllib3\connection.py", line 174, in _new_conn
    conn = connection.create_connection(
           ^^^^^^^^^^^^^^^^^^^^^^^^^^^^^
  File "C:\robot_work\.venv\Lib\site-packages\urllib3\util\connection.py", line 95, in create_connection
    raise err
  File "C:\robot_work\.venv\Lib\site-packages\urllib3\util\connection.py", line 85, in create_connection
    sock.connect(sa)
ConnectionRefusedError: [WinError 10061] 由于目标计算机积极拒绝，无法连接。

During handling of the above exception, another exception occurred:

Traceback (most recent call last):
  File "C:\robot_work\.venv\Lib\site-packages\urllib3\connectionpool.py", line 716, in urlopen
    httplib_response = self._make_request(
                       ^^^^^^^^^^^^^^^^^^^
  File "C:\robot_work\.venv\Lib\site-packages\urllib3\connectionpool.py", line 416, in _make_request
    conn.request(method, url, **httplib_request_kw)
  File "C:\robot_work\.venv\Lib\site-packages\urllib3\connection.py", line 244, in request
    super(HTTPConnection, self).request(method, url, body=body, headers=headers)
  File "C:\Users\张洛\AppData\Local\Programs\Python\Python312\Lib\http\client.py", line 1319, in request
    self._send_request(method, url, body, headers, encode_chunked)
  File "C:\Users\张洛\AppData\Local\Programs\Python\Python312\Lib\http\client.py", line 1365, in _send_request
    self.endheaders(body, encode_chunked=encode_chunked)
  File "C:\Users\张洛\AppData\Local\Programs\Python\Python312\Lib\http\client.py", line 1314, in endheaders
    self._send_output(message_body, encode_chunked=encode_chunked)
  File "C:\Users\张洛\AppData\Local\Programs\Python\Python312\Lib\http\client.py", line 1074, in _send_output
    self.send(msg)
  File "C:\Users\张洛\AppData\Local\Programs\Python\Python312\Lib\http\client.py", line 1018, in send
    self.connect()
  File "C:\robot_work\.venv\Lib\site-packages\urllib3\connection.py", line 205, in connect
    conn = self._new_conn()
           ^^^^^^^^^^^^^^^^
  File "C:\robot_work\.venv\Lib\site-packages\urllib3\connection.py", line 186, in _new_conn
    raise NewConnectionError(
urllib3.exceptions.NewConnectionError: <urllib3.connection.HTTPConnection object at 0x0000016953C6D010>: Failed to establish a new connection: [WinError 10061] 由于目标计算机积极拒绝，无法连接。

During handling of the above exception, another exception occurred:

Traceback (most recent call last):
  File "C:\robot_work\.venv\Lib\site-packages\requests\adapters.py", line 667, in send
    resp = conn.urlopen(
           ^^^^^^^^^^^^^
  File "C:\robot_work\.venv\Lib\site-packages\urllib3\connectionpool.py", line 802, in urlopen
    retries = retries.increment(
              ^^^^^^^^^^^^^^^^^^
  File "C:\robot_work\.venv\Lib\site-packages\urllib3\util\retry.py", line 594, in increment
    raise MaxRetryError(_pool, url, error or ResponseError(cause))
urllib3.exceptions.MaxRetryError: HTTPConnectionPool(host='localhost', port=6800): Max retries exceeded with url: / (Caused by NewConnectionError('<urllib3.connection.HTTPConnection object at 0x0000016953C6D010>: Failed to establish a new connection: [WinError 10061] 由于目标计算机积极拒绝，无法连接。'))

During handling of the above exception, another exception occurred:

Traceback (most recent call last):
  File "C:\robot_work\.venv\Lib\site-packages\gerapy\server\core\utils.py", line 562, in wrapper
    result = func(*args, **kwargs)
             ^^^^^^^^^^^^^^^^^^^^^
  File "C:\robot_work\.venv\Lib\site-packages\django\views\decorators\csrf.py", line 54, in wrapped_view
    return view_func(*args, **kwargs)
           ^^^^^^^^^^^^^^^^^^^^^^^^^^
  File "C:\robot_work\.venv\Lib\site-packages\django\views\generic\base.py", line 71, in view
    return self.dispatch(request, *args, **kwargs)
           ^^^^^^^^^^^^^^^^^^^^^^^^^^^^^^^^^^^^^^^
  File "C:\robot_work\.venv\Lib\site-packages\rest_framework\views.py", line 509, in dispatch
    response = self.handle_exception(exc)
               ^^^^^^^^^^^^^^^^^^^^^^^^^^
  File "C:\robot_work\.venv\Lib\site-packages\rest_framework\views.py", line 469, in handle_exception
    self.raise_uncaught_exception(exc)
  File "C:\robot_work\.venv\Lib\site-packages\rest_framework\views.py", line 480, in raise_uncaught_exception
    raise exc
  File "C:\robot_work\.venv\Lib\site-packages\rest_framework\views.py", line 506, in dispatch
    response = handler(request, *args, **kwargs)
               ^^^^^^^^^^^^^^^^^^^^^^^^^^^^^^^^^
  File "C:\robot_work\.venv\Lib\site-packages\rest_framework\decorators.py", line 50, in handler
    return func(*args, **kwargs)
           ^^^^^^^^^^^^^^^^^^^^^
  File "C:\robot_work\.venv\Lib\site-packages\gerapy\server\core\views.py", line 120, in client_status
    requests.get(scrapyd_url(client.ip, client.port), timeout=3)
  File "C:\robot_work\.venv\Lib\site-packages\requests\api.py", line 73, in get
    return request("get", url, params=params, **kwargs)
           ^^^^^^^^^^^^^^^^^^^^^^^^^^^^^^^^^^^^^^^^^^^^
  File "C:\robot_work\.venv\Lib\site-packages\requests\api.py", line 59, in request
    return session.request(method=method, url=url, **kwargs)
           ^^^^^^^^^^^^^^^^^^^^^^^^^^^^^^^^^^^^^^^^^^^^^^^^^
  File "C:\robot_work\.venv\Lib\site-packages\requests\sessions.py", line 589, in request
    resp = self.send(prep, **send_kwargs)
           ^^^^^^^^^^^^^^^^^^^^^^^^^^^^^^
  File "C:\robot_work\.venv\Lib\site-packages\requests\sessions.py", line 703, in send
    r = adapter.send(request, **kwargs)
        ^^^^^^^^^^^^^^^^^^^^^^^^^^^^^^^
  File "C:\robot_work\.venv\Lib\site-packages\requests\adapters.py", line 700, in send
    raise ConnectionError(e, request=request)
requests.exceptions.ConnectionError: HTTPConnectionPool(host='localhost', port=6800): Max retries exceeded with url: / (Caused by NewConnectionError('<urllib3.connection.HTTPConnection object at 0x0000016953C6D010>: Failed to establish a new connection: [WinError 10061] 由于目标计算机积极拒绝，无法连接。'))
ERROR - 2024-11-11 17:07:01,610 - process: 8332 - utils.py - gerapy.server.core.utils - 564 - utils - decode() argument 'encoding' must be str, not None
Traceback (most recent call last):
  File "C:\robot_work\.venv\Lib\site-packages\gerapy\server\core\utils.py", line 562, in wrapper
    result = func(*args, **kwargs)
             ^^^^^^^^^^^^^^^^^^^^^
  File "C:\robot_work\.venv\Lib\site-packages\django\views\decorators\csrf.py", line 54, in wrapped_view
    return view_func(*args, **kwargs)
           ^^^^^^^^^^^^^^^^^^^^^^^^^^
  File "C:\robot_work\.venv\Lib\site-packages\django\views\generic\base.py", line 71, in view
    return self.dispatch(request, *args, **kwargs)
           ^^^^^^^^^^^^^^^^^^^^^^^^^^^^^^^^^^^^^^^
  File "C:\robot_work\.venv\Lib\site-packages\rest_framework\views.py", line 509, in dispatch
    response = self.handle_exception(exc)
               ^^^^^^^^^^^^^^^^^^^^^^^^^^
  File "C:\robot_work\.venv\Lib\site-packages\rest_framework\views.py", line 469, in handle_exception
    self.raise_uncaught_exception(exc)
  File "C:\robot_work\.venv\Lib\site-packages\rest_framework\views.py", line 480, in raise_uncaught_exception
    raise exc
  File "C:\robot_work\.venv\Lib\site-packages\rest_framework\views.py", line 506, in dispatch
    response = handler(request, *args, **kwargs)
               ^^^^^^^^^^^^^^^^^^^^^^^^^^^^^^^^^
  File "C:\robot_work\.venv\Lib\site-packages\rest_framework\decorators.py", line 50, in handler
    return func(*args, **kwargs)
           ^^^^^^^^^^^^^^^^^^^^^
  File "C:\robot_work\.venv\Lib\site-packages\gerapy\server\core\views.py", line 728, in job_log
    text = response.content.decode(encoding, errors='replace')
           ^^^^^^^^^^^^^^^^^^^^^^^^^^^^^^^^^^^^^^^^^^^^^^^^^^^
TypeError: decode() argument 'encoding' must be str, not None
ERROR - 2024-11-11 17:28:54,832 - process: 8332 - utils.py - gerapy.server.core.utils - 564 - utils - HTTPConnectionPool(host='localhost', port=6800): Max retries exceeded with url: / (Caused by NewConnectionError('<urllib3.connection.HTTPConnection object at 0x00000169539C6630>: Failed to establish a new connection: [WinError 10061] 由于目标计算机积极拒绝，无法连接。'))
Traceback (most recent call last):
  File "C:\robot_work\.venv\Lib\site-packages\urllib3\connection.py", line 174, in _new_conn
    conn = connection.create_connection(
           ^^^^^^^^^^^^^^^^^^^^^^^^^^^^^
  File "C:\robot_work\.venv\Lib\site-packages\urllib3\util\connection.py", line 95, in create_connection
    raise err
  File "C:\robot_work\.venv\Lib\site-packages\urllib3\util\connection.py", line 85, in create_connection
    sock.connect(sa)
ConnectionRefusedError: [WinError 10061] 由于目标计算机积极拒绝，无法连接。

During handling of the above exception, another exception occurred:

Traceback (most recent call last):
  File "C:\robot_work\.venv\Lib\site-packages\urllib3\connectionpool.py", line 716, in urlopen
    httplib_response = self._make_request(
                       ^^^^^^^^^^^^^^^^^^^
  File "C:\robot_work\.venv\Lib\site-packages\urllib3\connectionpool.py", line 416, in _make_request
    conn.request(method, url, **httplib_request_kw)
  File "C:\robot_work\.venv\Lib\site-packages\urllib3\connection.py", line 244, in request
    super(HTTPConnection, self).request(method, url, body=body, headers=headers)
  File "C:\Users\张洛\AppData\Local\Programs\Python\Python312\Lib\http\client.py", line 1319, in request
    self._send_request(method, url, body, headers, encode_chunked)
  File "C:\Users\张洛\AppData\Local\Programs\Python\Python312\Lib\http\client.py", line 1365, in _send_request
    self.endheaders(body, encode_chunked=encode_chunked)
  File "C:\Users\张洛\AppData\Local\Programs\Python\Python312\Lib\http\client.py", line 1314, in endheaders
    self._send_output(message_body, encode_chunked=encode_chunked)
  File "C:\Users\张洛\AppData\Local\Programs\Python\Python312\Lib\http\client.py", line 1074, in _send_output
    self.send(msg)
  File "C:\Users\张洛\AppData\Local\Programs\Python\Python312\Lib\http\client.py", line 1018, in send
    self.connect()
  File "C:\robot_work\.venv\Lib\site-packages\urllib3\connection.py", line 205, in connect
    conn = self._new_conn()
           ^^^^^^^^^^^^^^^^
  File "C:\robot_work\.venv\Lib\site-packages\urllib3\connection.py", line 186, in _new_conn
    raise NewConnectionError(
urllib3.exceptions.NewConnectionError: <urllib3.connection.HTTPConnection object at 0x00000169539C6630>: Failed to establish a new connection: [WinError 10061] 由于目标计算机积极拒绝，无法连接。

During handling of the above exception, another exception occurred:

Traceback (most recent call last):
  File "C:\robot_work\.venv\Lib\site-packages\requests\adapters.py", line 667, in send
    resp = conn.urlopen(
           ^^^^^^^^^^^^^
  File "C:\robot_work\.venv\Lib\site-packages\urllib3\connectionpool.py", line 802, in urlopen
    retries = retries.increment(
              ^^^^^^^^^^^^^^^^^^
  File "C:\robot_work\.venv\Lib\site-packages\urllib3\util\retry.py", line 594, in increment
    raise MaxRetryError(_pool, url, error or ResponseError(cause))
urllib3.exceptions.MaxRetryError: HTTPConnectionPool(host='localhost', port=6800): Max retries exceeded with url: / (Caused by NewConnectionError('<urllib3.connection.HTTPConnection object at 0x00000169539C6630>: Failed to establish a new connection: [WinError 10061] 由于目标计算机积极拒绝，无法连接。'))

During handling of the above exception, another exception occurred:

Traceback (most recent call last):
  File "C:\robot_work\.venv\Lib\site-packages\gerapy\server\core\utils.py", line 562, in wrapper
    result = func(*args, **kwargs)
             ^^^^^^^^^^^^^^^^^^^^^
  File "C:\robot_work\.venv\Lib\site-packages\django\views\decorators\csrf.py", line 54, in wrapped_view
    return view_func(*args, **kwargs)
           ^^^^^^^^^^^^^^^^^^^^^^^^^^
  File "C:\robot_work\.venv\Lib\site-packages\django\views\generic\base.py", line 71, in view
    return self.dispatch(request, *args, **kwargs)
           ^^^^^^^^^^^^^^^^^^^^^^^^^^^^^^^^^^^^^^^
  File "C:\robot_work\.venv\Lib\site-packages\rest_framework\views.py", line 509, in dispatch
    response = self.handle_exception(exc)
               ^^^^^^^^^^^^^^^^^^^^^^^^^^
  File "C:\robot_work\.venv\Lib\site-packages\rest_framework\views.py", line 469, in handle_exception
    self.raise_uncaught_exception(exc)
  File "C:\robot_work\.venv\Lib\site-packages\rest_framework\views.py", line 480, in raise_uncaught_exception
    raise exc
  File "C:\robot_work\.venv\Lib\site-packages\rest_framework\views.py", line 506, in dispatch
    response = handler(request, *args, **kwargs)
               ^^^^^^^^^^^^^^^^^^^^^^^^^^^^^^^^^
  File "C:\robot_work\.venv\Lib\site-packages\rest_framework\decorators.py", line 50, in handler
    return func(*args, **kwargs)
           ^^^^^^^^^^^^^^^^^^^^^
  File "C:\robot_work\.venv\Lib\site-packages\gerapy\server\core\views.py", line 120, in client_status
    requests.get(scrapyd_url(client.ip, client.port), timeout=3)
  File "C:\robot_work\.venv\Lib\site-packages\requests\api.py", line 73, in get
    return request("get", url, params=params, **kwargs)
           ^^^^^^^^^^^^^^^^^^^^^^^^^^^^^^^^^^^^^^^^^^^^
  File "C:\robot_work\.venv\Lib\site-packages\requests\api.py", line 59, in request
    return session.request(method=method, url=url, **kwargs)
           ^^^^^^^^^^^^^^^^^^^^^^^^^^^^^^^^^^^^^^^^^^^^^^^^^
  File "C:\robot_work\.venv\Lib\site-packages\requests\sessions.py", line 589, in request
    resp = self.send(prep, **send_kwargs)
           ^^^^^^^^^^^^^^^^^^^^^^^^^^^^^^
  File "C:\robot_work\.venv\Lib\site-packages\requests\sessions.py", line 703, in send
    r = adapter.send(request, **kwargs)
        ^^^^^^^^^^^^^^^^^^^^^^^^^^^^^^^
  File "C:\robot_work\.venv\Lib\site-packages\requests\adapters.py", line 700, in send
    raise ConnectionError(e, request=request)
requests.exceptions.ConnectionError: HTTPConnectionPool(host='localhost', port=6800): Max retries exceeded with url: / (Caused by NewConnectionError('<urllib3.connection.HTTPConnection object at 0x00000169539C6630>: Failed to establish a new connection: [WinError 10061] 由于目标计算机积极拒绝，无法连接。'))
ERROR - 2024-11-11 17:28:57,907 - process: 8332 - utils.py - gerapy.server.core.utils - 564 - utils - HTTPConnectionPool(host='localhost', port=6800): Max retries exceeded with url: /listprojects.json (Caused by NewConnectionError('<urllib3.connection.HTTPConnection object at 0x00000169539E5DF0>: Failed to establish a new connection: [WinError 10061] 由于目标计算机积极拒绝，无法连接。'))
Traceback (most recent call last):
  File "C:\robot_work\.venv\Lib\site-packages\urllib3\connection.py", line 174, in _new_conn
    conn = connection.create_connection(
           ^^^^^^^^^^^^^^^^^^^^^^^^^^^^^
  File "C:\robot_work\.venv\Lib\site-packages\urllib3\util\connection.py", line 95, in create_connection
    raise err
  File "C:\robot_work\.venv\Lib\site-packages\urllib3\util\connection.py", line 85, in create_connection
    sock.connect(sa)
ConnectionRefusedError: [WinError 10061] 由于目标计算机积极拒绝，无法连接。

During handling of the above exception, another exception occurred:

Traceback (most recent call last):
  File "C:\robot_work\.venv\Lib\site-packages\urllib3\connectionpool.py", line 716, in urlopen
    httplib_response = self._make_request(
                       ^^^^^^^^^^^^^^^^^^^
  File "C:\robot_work\.venv\Lib\site-packages\urllib3\connectionpool.py", line 416, in _make_request
    conn.request(method, url, **httplib_request_kw)
  File "C:\robot_work\.venv\Lib\site-packages\urllib3\connection.py", line 244, in request
    super(HTTPConnection, self).request(method, url, body=body, headers=headers)
  File "C:\Users\张洛\AppData\Local\Programs\Python\Python312\Lib\http\client.py", line 1319, in request
    self._send_request(method, url, body, headers, encode_chunked)
  File "C:\Users\张洛\AppData\Local\Programs\Python\Python312\Lib\http\client.py", line 1365, in _send_request
    self.endheaders(body, encode_chunked=encode_chunked)
  File "C:\Users\张洛\AppData\Local\Programs\Python\Python312\Lib\http\client.py", line 1314, in endheaders
    self._send_output(message_body, encode_chunked=encode_chunked)
  File "C:\Users\张洛\AppData\Local\Programs\Python\Python312\Lib\http\client.py", line 1074, in _send_output
    self.send(msg)
  File "C:\Users\张洛\AppData\Local\Programs\Python\Python312\Lib\http\client.py", line 1018, in send
    self.connect()
  File "C:\robot_work\.venv\Lib\site-packages\urllib3\connection.py", line 205, in connect
    conn = self._new_conn()
           ^^^^^^^^^^^^^^^^
  File "C:\robot_work\.venv\Lib\site-packages\urllib3\connection.py", line 186, in _new_conn
    raise NewConnectionError(
urllib3.exceptions.NewConnectionError: <urllib3.connection.HTTPConnection object at 0x00000169539E5DF0>: Failed to establish a new connection: [WinError 10061] 由于目标计算机积极拒绝，无法连接。

During handling of the above exception, another exception occurred:

Traceback (most recent call last):
  File "C:\robot_work\.venv\Lib\site-packages\requests\adapters.py", line 667, in send
    resp = conn.urlopen(
           ^^^^^^^^^^^^^
  File "C:\robot_work\.venv\Lib\site-packages\urllib3\connectionpool.py", line 802, in urlopen
    retries = retries.increment(
              ^^^^^^^^^^^^^^^^^^
  File "C:\robot_work\.venv\Lib\site-packages\urllib3\util\retry.py", line 594, in increment
    raise MaxRetryError(_pool, url, error or ResponseError(cause))
urllib3.exceptions.MaxRetryError: HTTPConnectionPool(host='localhost', port=6800): Max retries exceeded with url: /listprojects.json (Caused by NewConnectionError('<urllib3.connection.HTTPConnection object at 0x00000169539E5DF0>: Failed to establish a new connection: [WinError 10061] 由于目标计算机积极拒绝，无法连接。'))

During handling of the above exception, another exception occurred:

Traceback (most recent call last):
  File "C:\robot_work\.venv\Lib\site-packages\gerapy\server\core\utils.py", line 562, in wrapper
    result = func(*args, **kwargs)
             ^^^^^^^^^^^^^^^^^^^^^
  File "C:\robot_work\.venv\Lib\site-packages\django\views\decorators\csrf.py", line 54, in wrapped_view
    return view_func(*args, **kwargs)
           ^^^^^^^^^^^^^^^^^^^^^^^^^^
  File "C:\robot_work\.venv\Lib\site-packages\django\views\generic\base.py", line 71, in view
    return self.dispatch(request, *args, **kwargs)
           ^^^^^^^^^^^^^^^^^^^^^^^^^^^^^^^^^^^^^^^
  File "C:\robot_work\.venv\Lib\site-packages\rest_framework\views.py", line 509, in dispatch
    response = self.handle_exception(exc)
               ^^^^^^^^^^^^^^^^^^^^^^^^^^
  File "C:\robot_work\.venv\Lib\site-packages\rest_framework\views.py", line 469, in handle_exception
    self.raise_uncaught_exception(exc)
  File "C:\robot_work\.venv\Lib\site-packages\rest_framework\views.py", line 480, in raise_uncaught_exception
    raise exc
  File "C:\robot_work\.venv\Lib\site-packages\rest_framework\views.py", line 506, in dispatch
    response = handler(request, *args, **kwargs)
               ^^^^^^^^^^^^^^^^^^^^^^^^^^^^^^^^^
  File "C:\robot_work\.venv\Lib\site-packages\rest_framework\decorators.py", line 50, in handler
    return func(*args, **kwargs)
           ^^^^^^^^^^^^^^^^^^^^^
  File "C:\robot_work\.venv\Lib\site-packages\gerapy\server\core\views.py", line 227, in project_list
    projects = scrapyd.list_projects()
               ^^^^^^^^^^^^^^^^^^^^^^^
  File "C:\robot_work\.venv\Lib\site-packages\scrapyd_api\wrapper.py", line 148, in list_projects
    json = self.client.get(url, timeout=self.timeout)
           ^^^^^^^^^^^^^^^^^^^^^^^^^^^^^^^^^^^^^^^^^^
  File "C:\robot_work\.venv\Lib\site-packages\requests\sessions.py", line 602, in get
    return self.request("GET", url, **kwargs)
           ^^^^^^^^^^^^^^^^^^^^^^^^^^^^^^^^^^
  File "C:\robot_work\.venv\Lib\site-packages\scrapyd_api\client.py", line 37, in request
    response = super(Client, self).request(*args, **kwargs)
               ^^^^^^^^^^^^^^^^^^^^^^^^^^^^^^^^^^^^^^^^^^^^
  File "C:\robot_work\.venv\Lib\site-packages\requests\sessions.py", line 589, in request
    resp = self.send(prep, **send_kwargs)
           ^^^^^^^^^^^^^^^^^^^^^^^^^^^^^^
  File "C:\robot_work\.venv\Lib\site-packages\requests\sessions.py", line 703, in send
    r = adapter.send(request, **kwargs)
        ^^^^^^^^^^^^^^^^^^^^^^^^^^^^^^^
  File "C:\robot_work\.venv\Lib\site-packages\requests\adapters.py", line 700, in send
    raise ConnectionError(e, request=request)
requests.exceptions.ConnectionError: HTTPConnectionPool(host='localhost', port=6800): Max retries exceeded with url: /listprojects.json (Caused by NewConnectionError('<urllib3.connection.HTTPConnection object at 0x00000169539E5DF0>: Failed to establish a new connection: [WinError 10061] 由于目标计算机积极拒绝，无法连接。'))
ERROR - 2024-11-11 17:28:59,540 - process: 8332 - utils.py - gerapy.server.core.utils - 564 - utils - HTTPConnectionPool(host='localhost', port=6800): Max retries exceeded with url: / (Caused by NewConnectionError('<urllib3.connection.HTTPConnection object at 0x00000169539C4D70>: Failed to establish a new connection: [WinError 10061] 由于目标计算机积极拒绝，无法连接。'))
Traceback (most recent call last):
  File "C:\robot_work\.venv\Lib\site-packages\urllib3\connection.py", line 174, in _new_conn
    conn = connection.create_connection(
           ^^^^^^^^^^^^^^^^^^^^^^^^^^^^^
  File "C:\robot_work\.venv\Lib\site-packages\urllib3\util\connection.py", line 95, in create_connection
    raise err
  File "C:\robot_work\.venv\Lib\site-packages\urllib3\util\connection.py", line 85, in create_connection
    sock.connect(sa)
ConnectionRefusedError: [WinError 10061] 由于目标计算机积极拒绝，无法连接。

During handling of the above exception, another exception occurred:

Traceback (most recent call last):
  File "C:\robot_work\.venv\Lib\site-packages\urllib3\connectionpool.py", line 716, in urlopen
    httplib_response = self._make_request(
                       ^^^^^^^^^^^^^^^^^^^
  File "C:\robot_work\.venv\Lib\site-packages\urllib3\connectionpool.py", line 416, in _make_request
    conn.request(method, url, **httplib_request_kw)
  File "C:\robot_work\.venv\Lib\site-packages\urllib3\connection.py", line 244, in request
    super(HTTPConnection, self).request(method, url, body=body, headers=headers)
  File "C:\Users\张洛\AppData\Local\Programs\Python\Python312\Lib\http\client.py", line 1319, in request
    self._send_request(method, url, body, headers, encode_chunked)
  File "C:\Users\张洛\AppData\Local\Programs\Python\Python312\Lib\http\client.py", line 1365, in _send_request
    self.endheaders(body, encode_chunked=encode_chunked)
  File "C:\Users\张洛\AppData\Local\Programs\Python\Python312\Lib\http\client.py", line 1314, in endheaders
    self._send_output(message_body, encode_chunked=encode_chunked)
  File "C:\Users\张洛\AppData\Local\Programs\Python\Python312\Lib\http\client.py", line 1074, in _send_output
    self.send(msg)
  File "C:\Users\张洛\AppData\Local\Programs\Python\Python312\Lib\http\client.py", line 1018, in send
    self.connect()
  File "C:\robot_work\.venv\Lib\site-packages\urllib3\connection.py", line 205, in connect
    conn = self._new_conn()
           ^^^^^^^^^^^^^^^^
  File "C:\robot_work\.venv\Lib\site-packages\urllib3\connection.py", line 186, in _new_conn
    raise NewConnectionError(
urllib3.exceptions.NewConnectionError: <urllib3.connection.HTTPConnection object at 0x00000169539C4D70>: Failed to establish a new connection: [WinError 10061] 由于目标计算机积极拒绝，无法连接。

During handling of the above exception, another exception occurred:

Traceback (most recent call last):
  File "C:\robot_work\.venv\Lib\site-packages\requests\adapters.py", line 667, in send
    resp = conn.urlopen(
           ^^^^^^^^^^^^^
  File "C:\robot_work\.venv\Lib\site-packages\urllib3\connectionpool.py", line 802, in urlopen
    retries = retries.increment(
              ^^^^^^^^^^^^^^^^^^
  File "C:\robot_work\.venv\Lib\site-packages\urllib3\util\retry.py", line 594, in increment
    raise MaxRetryError(_pool, url, error or ResponseError(cause))
urllib3.exceptions.MaxRetryError: HTTPConnectionPool(host='localhost', port=6800): Max retries exceeded with url: / (Caused by NewConnectionError('<urllib3.connection.HTTPConnection object at 0x00000169539C4D70>: Failed to establish a new connection: [WinError 10061] 由于目标计算机积极拒绝，无法连接。'))

During handling of the above exception, another exception occurred:

Traceback (most recent call last):
  File "C:\robot_work\.venv\Lib\site-packages\gerapy\server\core\utils.py", line 562, in wrapper
    result = func(*args, **kwargs)
             ^^^^^^^^^^^^^^^^^^^^^
  File "C:\robot_work\.venv\Lib\site-packages\django\views\decorators\csrf.py", line 54, in wrapped_view
    return view_func(*args, **kwargs)
           ^^^^^^^^^^^^^^^^^^^^^^^^^^
  File "C:\robot_work\.venv\Lib\site-packages\django\views\generic\base.py", line 71, in view
    return self.dispatch(request, *args, **kwargs)
           ^^^^^^^^^^^^^^^^^^^^^^^^^^^^^^^^^^^^^^^
  File "C:\robot_work\.venv\Lib\site-packages\rest_framework\views.py", line 509, in dispatch
    response = self.handle_exception(exc)
               ^^^^^^^^^^^^^^^^^^^^^^^^^^
  File "C:\robot_work\.venv\Lib\site-packages\rest_framework\views.py", line 469, in handle_exception
    self.raise_uncaught_exception(exc)
  File "C:\robot_work\.venv\Lib\site-packages\rest_framework\views.py", line 480, in raise_uncaught_exception
    raise exc
  File "C:\robot_work\.venv\Lib\site-packages\rest_framework\views.py", line 506, in dispatch
    response = handler(request, *args, **kwargs)
               ^^^^^^^^^^^^^^^^^^^^^^^^^^^^^^^^^
  File "C:\robot_work\.venv\Lib\site-packages\rest_framework\decorators.py", line 50, in handler
    return func(*args, **kwargs)
           ^^^^^^^^^^^^^^^^^^^^^
  File "C:\robot_work\.venv\Lib\site-packages\gerapy\server\core\views.py", line 120, in client_status
    requests.get(scrapyd_url(client.ip, client.port), timeout=3)
  File "C:\robot_work\.venv\Lib\site-packages\requests\api.py", line 73, in get
    return request("get", url, params=params, **kwargs)
           ^^^^^^^^^^^^^^^^^^^^^^^^^^^^^^^^^^^^^^^^^^^^
  File "C:\robot_work\.venv\Lib\site-packages\requests\api.py", line 59, in request
    return session.request(method=method, url=url, **kwargs)
           ^^^^^^^^^^^^^^^^^^^^^^^^^^^^^^^^^^^^^^^^^^^^^^^^^
  File "C:\robot_work\.venv\Lib\site-packages\requests\sessions.py", line 589, in request
    resp = self.send(prep, **send_kwargs)
           ^^^^^^^^^^^^^^^^^^^^^^^^^^^^^^
  File "C:\robot_work\.venv\Lib\site-packages\requests\sessions.py", line 703, in send
    r = adapter.send(request, **kwargs)
        ^^^^^^^^^^^^^^^^^^^^^^^^^^^^^^^
  File "C:\robot_work\.venv\Lib\site-packages\requests\adapters.py", line 700, in send
    raise ConnectionError(e, request=request)
requests.exceptions.ConnectionError: HTTPConnectionPool(host='localhost', port=6800): Max retries exceeded with url: / (Caused by NewConnectionError('<urllib3.connection.HTTPConnection object at 0x00000169539C4D70>: Failed to establish a new connection: [WinError 10061] 由于目标计算机积极拒绝，无法连接。'))
ERROR - 2024-11-11 17:29:02,559 - process: 8332 - utils.py - gerapy.server.core.utils - 564 - utils - HTTPConnectionPool(host='localhost', port=6800): Max retries exceeded with url: /listprojects.json (Caused by NewConnectionError('<urllib3.connection.HTTPConnection object at 0x00000169536639E0>: Failed to establish a new connection: [WinError 10061] 由于目标计算机积极拒绝，无法连接。'))
Traceback (most recent call last):
  File "C:\robot_work\.venv\Lib\site-packages\urllib3\connection.py", line 174, in _new_conn
    conn = connection.create_connection(
           ^^^^^^^^^^^^^^^^^^^^^^^^^^^^^
  File "C:\robot_work\.venv\Lib\site-packages\urllib3\util\connection.py", line 95, in create_connection
    raise err
  File "C:\robot_work\.venv\Lib\site-packages\urllib3\util\connection.py", line 85, in create_connection
    sock.connect(sa)
ConnectionRefusedError: [WinError 10061] 由于目标计算机积极拒绝，无法连接。

During handling of the above exception, another exception occurred:

Traceback (most recent call last):
  File "C:\robot_work\.venv\Lib\site-packages\urllib3\connectionpool.py", line 716, in urlopen
    httplib_response = self._make_request(
                       ^^^^^^^^^^^^^^^^^^^
  File "C:\robot_work\.venv\Lib\site-packages\urllib3\connectionpool.py", line 416, in _make_request
    conn.request(method, url, **httplib_request_kw)
  File "C:\robot_work\.venv\Lib\site-packages\urllib3\connection.py", line 244, in request
    super(HTTPConnection, self).request(method, url, body=body, headers=headers)
  File "C:\Users\张洛\AppData\Local\Programs\Python\Python312\Lib\http\client.py", line 1319, in request
    self._send_request(method, url, body, headers, encode_chunked)
  File "C:\Users\张洛\AppData\Local\Programs\Python\Python312\Lib\http\client.py", line 1365, in _send_request
    self.endheaders(body, encode_chunked=encode_chunked)
  File "C:\Users\张洛\AppData\Local\Programs\Python\Python312\Lib\http\client.py", line 1314, in endheaders
    self._send_output(message_body, encode_chunked=encode_chunked)
  File "C:\Users\张洛\AppData\Local\Programs\Python\Python312\Lib\http\client.py", line 1074, in _send_output
    self.send(msg)
  File "C:\Users\张洛\AppData\Local\Programs\Python\Python312\Lib\http\client.py", line 1018, in send
    self.connect()
  File "C:\robot_work\.venv\Lib\site-packages\urllib3\connection.py", line 205, in connect
    conn = self._new_conn()
           ^^^^^^^^^^^^^^^^
  File "C:\robot_work\.venv\Lib\site-packages\urllib3\connection.py", line 186, in _new_conn
    raise NewConnectionError(
urllib3.exceptions.NewConnectionError: <urllib3.connection.HTTPConnection object at 0x00000169536639E0>: Failed to establish a new connection: [WinError 10061] 由于目标计算机积极拒绝，无法连接。

During handling of the above exception, another exception occurred:

Traceback (most recent call last):
  File "C:\robot_work\.venv\Lib\site-packages\requests\adapters.py", line 667, in send
    resp = conn.urlopen(
           ^^^^^^^^^^^^^
  File "C:\robot_work\.venv\Lib\site-packages\urllib3\connectionpool.py", line 802, in urlopen
    retries = retries.increment(
              ^^^^^^^^^^^^^^^^^^
  File "C:\robot_work\.venv\Lib\site-packages\urllib3\util\retry.py", line 594, in increment
    raise MaxRetryError(_pool, url, error or ResponseError(cause))
urllib3.exceptions.MaxRetryError: HTTPConnectionPool(host='localhost', port=6800): Max retries exceeded with url: /listprojects.json (Caused by NewConnectionError('<urllib3.connection.HTTPConnection object at 0x00000169536639E0>: Failed to establish a new connection: [WinError 10061] 由于目标计算机积极拒绝，无法连接。'))

During handling of the above exception, another exception occurred:

Traceback (most recent call last):
  File "C:\robot_work\.venv\Lib\site-packages\gerapy\server\core\utils.py", line 562, in wrapper
    result = func(*args, **kwargs)
             ^^^^^^^^^^^^^^^^^^^^^
  File "C:\robot_work\.venv\Lib\site-packages\django\views\decorators\csrf.py", line 54, in wrapped_view
    return view_func(*args, **kwargs)
           ^^^^^^^^^^^^^^^^^^^^^^^^^^
  File "C:\robot_work\.venv\Lib\site-packages\django\views\generic\base.py", line 71, in view
    return self.dispatch(request, *args, **kwargs)
           ^^^^^^^^^^^^^^^^^^^^^^^^^^^^^^^^^^^^^^^
  File "C:\robot_work\.venv\Lib\site-packages\rest_framework\views.py", line 509, in dispatch
    response = self.handle_exception(exc)
               ^^^^^^^^^^^^^^^^^^^^^^^^^^
  File "C:\robot_work\.venv\Lib\site-packages\rest_framework\views.py", line 469, in handle_exception
    self.raise_uncaught_exception(exc)
  File "C:\robot_work\.venv\Lib\site-packages\rest_framework\views.py", line 480, in raise_uncaught_exception
    raise exc
  File "C:\robot_work\.venv\Lib\site-packages\rest_framework\views.py", line 506, in dispatch
    response = handler(request, *args, **kwargs)
               ^^^^^^^^^^^^^^^^^^^^^^^^^^^^^^^^^
  File "C:\robot_work\.venv\Lib\site-packages\rest_framework\decorators.py", line 50, in handler
    return func(*args, **kwargs)
           ^^^^^^^^^^^^^^^^^^^^^
  File "C:\robot_work\.venv\Lib\site-packages\gerapy\server\core\views.py", line 227, in project_list
    projects = scrapyd.list_projects()
               ^^^^^^^^^^^^^^^^^^^^^^^
  File "C:\robot_work\.venv\Lib\site-packages\scrapyd_api\wrapper.py", line 148, in list_projects
    json = self.client.get(url, timeout=self.timeout)
           ^^^^^^^^^^^^^^^^^^^^^^^^^^^^^^^^^^^^^^^^^^
  File "C:\robot_work\.venv\Lib\site-packages\requests\sessions.py", line 602, in get
    return self.request("GET", url, **kwargs)
           ^^^^^^^^^^^^^^^^^^^^^^^^^^^^^^^^^^
  File "C:\robot_work\.venv\Lib\site-packages\scrapyd_api\client.py", line 37, in request
    response = super(Client, self).request(*args, **kwargs)
               ^^^^^^^^^^^^^^^^^^^^^^^^^^^^^^^^^^^^^^^^^^^^
  File "C:\robot_work\.venv\Lib\site-packages\requests\sessions.py", line 589, in request
    resp = self.send(prep, **send_kwargs)
           ^^^^^^^^^^^^^^^^^^^^^^^^^^^^^^
  File "C:\robot_work\.venv\Lib\site-packages\requests\sessions.py", line 703, in send
    r = adapter.send(request, **kwargs)
        ^^^^^^^^^^^^^^^^^^^^^^^^^^^^^^^
  File "C:\robot_work\.venv\Lib\site-packages\requests\adapters.py", line 700, in send
    raise ConnectionError(e, request=request)
requests.exceptions.ConnectionError: HTTPConnectionPool(host='localhost', port=6800): Max retries exceeded with url: /listprojects.json (Caused by NewConnectionError('<urllib3.connection.HTTPConnection object at 0x00000169536639E0>: Failed to establish a new connection: [WinError 10061] 由于目标计算机积极拒绝，无法连接。'))
ERROR - 2024-11-11 17:29:07,137 - process: 8332 - utils.py - gerapy.server.core.utils - 564 - utils - HTTPConnectionPool(host='localhost', port=6800): Max retries exceeded with url: /listprojects.json (Caused by NewConnectionError('<urllib3.connection.HTTPConnection object at 0x0000016953B79C40>: Failed to establish a new connection: [WinError 10061] 由于目标计算机积极拒绝，无法连接。'))
Traceback (most recent call last):
  File "C:\robot_work\.venv\Lib\site-packages\urllib3\connection.py", line 174, in _new_conn
    conn = connection.create_connection(
           ^^^^^^^^^^^^^^^^^^^^^^^^^^^^^
  File "C:\robot_work\.venv\Lib\site-packages\urllib3\util\connection.py", line 95, in create_connection
    raise err
  File "C:\robot_work\.venv\Lib\site-packages\urllib3\util\connection.py", line 85, in create_connection
    sock.connect(sa)
ConnectionRefusedError: [WinError 10061] 由于目标计算机积极拒绝，无法连接。

During handling of the above exception, another exception occurred:

Traceback (most recent call last):
  File "C:\robot_work\.venv\Lib\site-packages\urllib3\connectionpool.py", line 716, in urlopen
    httplib_response = self._make_request(
                       ^^^^^^^^^^^^^^^^^^^
  File "C:\robot_work\.venv\Lib\site-packages\urllib3\connectionpool.py", line 416, in _make_request
    conn.request(method, url, **httplib_request_kw)
  File "C:\robot_work\.venv\Lib\site-packages\urllib3\connection.py", line 244, in request
    super(HTTPConnection, self).request(method, url, body=body, headers=headers)
  File "C:\Users\张洛\AppData\Local\Programs\Python\Python312\Lib\http\client.py", line 1319, in request
    self._send_request(method, url, body, headers, encode_chunked)
  File "C:\Users\张洛\AppData\Local\Programs\Python\Python312\Lib\http\client.py", line 1365, in _send_request
    self.endheaders(body, encode_chunked=encode_chunked)
  File "C:\Users\张洛\AppData\Local\Programs\Python\Python312\Lib\http\client.py", line 1314, in endheaders
    self._send_output(message_body, encode_chunked=encode_chunked)
  File "C:\Users\张洛\AppData\Local\Programs\Python\Python312\Lib\http\client.py", line 1074, in _send_output
    self.send(msg)
  File "C:\Users\张洛\AppData\Local\Programs\Python\Python312\Lib\http\client.py", line 1018, in send
    self.connect()
  File "C:\robot_work\.venv\Lib\site-packages\urllib3\connection.py", line 205, in connect
    conn = self._new_conn()
           ^^^^^^^^^^^^^^^^
  File "C:\robot_work\.venv\Lib\site-packages\urllib3\connection.py", line 186, in _new_conn
    raise NewConnectionError(
urllib3.exceptions.NewConnectionError: <urllib3.connection.HTTPConnection object at 0x0000016953B79C40>: Failed to establish a new connection: [WinError 10061] 由于目标计算机积极拒绝，无法连接。

During handling of the above exception, another exception occurred:

Traceback (most recent call last):
  File "C:\robot_work\.venv\Lib\site-packages\requests\adapters.py", line 667, in send
    resp = conn.urlopen(
           ^^^^^^^^^^^^^
  File "C:\robot_work\.venv\Lib\site-packages\urllib3\connectionpool.py", line 802, in urlopen
    retries = retries.increment(
              ^^^^^^^^^^^^^^^^^^
  File "C:\robot_work\.venv\Lib\site-packages\urllib3\util\retry.py", line 594, in increment
    raise MaxRetryError(_pool, url, error or ResponseError(cause))
urllib3.exceptions.MaxRetryError: HTTPConnectionPool(host='localhost', port=6800): Max retries exceeded with url: /listprojects.json (Caused by NewConnectionError('<urllib3.connection.HTTPConnection object at 0x0000016953B79C40>: Failed to establish a new connection: [WinError 10061] 由于目标计算机积极拒绝，无法连接。'))

During handling of the above exception, another exception occurred:

Traceback (most recent call last):
  File "C:\robot_work\.venv\Lib\site-packages\gerapy\server\core\utils.py", line 562, in wrapper
    result = func(*args, **kwargs)
             ^^^^^^^^^^^^^^^^^^^^^
  File "C:\robot_work\.venv\Lib\site-packages\django\views\decorators\csrf.py", line 54, in wrapped_view
    return view_func(*args, **kwargs)
           ^^^^^^^^^^^^^^^^^^^^^^^^^^
  File "C:\robot_work\.venv\Lib\site-packages\django\views\generic\base.py", line 71, in view
    return self.dispatch(request, *args, **kwargs)
           ^^^^^^^^^^^^^^^^^^^^^^^^^^^^^^^^^^^^^^^
  File "C:\robot_work\.venv\Lib\site-packages\rest_framework\views.py", line 509, in dispatch
    response = self.handle_exception(exc)
               ^^^^^^^^^^^^^^^^^^^^^^^^^^
  File "C:\robot_work\.venv\Lib\site-packages\rest_framework\views.py", line 469, in handle_exception
    self.raise_uncaught_exception(exc)
  File "C:\robot_work\.venv\Lib\site-packages\rest_framework\views.py", line 480, in raise_uncaught_exception
    raise exc
  File "C:\robot_work\.venv\Lib\site-packages\rest_framework\views.py", line 506, in dispatch
    response = handler(request, *args, **kwargs)
               ^^^^^^^^^^^^^^^^^^^^^^^^^^^^^^^^^
  File "C:\robot_work\.venv\Lib\site-packages\rest_framework\decorators.py", line 50, in handler
    return func(*args, **kwargs)
           ^^^^^^^^^^^^^^^^^^^^^
  File "C:\robot_work\.venv\Lib\site-packages\gerapy\server\core\views.py", line 227, in project_list
    projects = scrapyd.list_projects()
               ^^^^^^^^^^^^^^^^^^^^^^^
  File "C:\robot_work\.venv\Lib\site-packages\scrapyd_api\wrapper.py", line 148, in list_projects
    json = self.client.get(url, timeout=self.timeout)
           ^^^^^^^^^^^^^^^^^^^^^^^^^^^^^^^^^^^^^^^^^^
  File "C:\robot_work\.venv\Lib\site-packages\requests\sessions.py", line 602, in get
    return self.request("GET", url, **kwargs)
           ^^^^^^^^^^^^^^^^^^^^^^^^^^^^^^^^^^
  File "C:\robot_work\.venv\Lib\site-packages\scrapyd_api\client.py", line 37, in request
    response = super(Client, self).request(*args, **kwargs)
               ^^^^^^^^^^^^^^^^^^^^^^^^^^^^^^^^^^^^^^^^^^^^
  File "C:\robot_work\.venv\Lib\site-packages\requests\sessions.py", line 589, in request
    resp = self.send(prep, **send_kwargs)
           ^^^^^^^^^^^^^^^^^^^^^^^^^^^^^^
  File "C:\robot_work\.venv\Lib\site-packages\requests\sessions.py", line 703, in send
    r = adapter.send(request, **kwargs)
        ^^^^^^^^^^^^^^^^^^^^^^^^^^^^^^^
  File "C:\robot_work\.venv\Lib\site-packages\requests\adapters.py", line 700, in send
    raise ConnectionError(e, request=request)
requests.exceptions.ConnectionError: HTTPConnectionPool(host='localhost', port=6800): Max retries exceeded with url: /listprojects.json (Caused by NewConnectionError('<urllib3.connection.HTTPConnection object at 0x0000016953B79C40>: Failed to establish a new connection: [WinError 10061] 由于目标计算机积极拒绝，无法连接。'))
ERROR - 2024-11-11 18:12:51,198 - process: 8332 - utils.py - gerapy.server.core.utils - 564 - utils - HTTPConnectionPool(host='localhost', port=6800): Max retries exceeded with url: /listjobs.json?project=robot_work (Caused by NewConnectionError('<urllib3.connection.HTTPConnection object at 0x0000016953D126F0>: Failed to establish a new connection: [WinError 10061] 由于目标计算机积极拒绝，无法连接。'))
Traceback (most recent call last):
  File "C:\robot_work\.venv\Lib\site-packages\urllib3\connection.py", line 174, in _new_conn
    conn = connection.create_connection(
           ^^^^^^^^^^^^^^^^^^^^^^^^^^^^^
  File "C:\robot_work\.venv\Lib\site-packages\urllib3\util\connection.py", line 95, in create_connection
    raise err
  File "C:\robot_work\.venv\Lib\site-packages\urllib3\util\connection.py", line 85, in create_connection
    sock.connect(sa)
ConnectionRefusedError: [WinError 10061] 由于目标计算机积极拒绝，无法连接。

During handling of the above exception, another exception occurred:

Traceback (most recent call last):
  File "C:\robot_work\.venv\Lib\site-packages\urllib3\connectionpool.py", line 716, in urlopen
    httplib_response = self._make_request(
                       ^^^^^^^^^^^^^^^^^^^
  File "C:\robot_work\.venv\Lib\site-packages\urllib3\connectionpool.py", line 416, in _make_request
    conn.request(method, url, **httplib_request_kw)
  File "C:\robot_work\.venv\Lib\site-packages\urllib3\connection.py", line 244, in request
    super(HTTPConnection, self).request(method, url, body=body, headers=headers)
  File "C:\Users\张洛\AppData\Local\Programs\Python\Python312\Lib\http\client.py", line 1319, in request
    self._send_request(method, url, body, headers, encode_chunked)
  File "C:\Users\张洛\AppData\Local\Programs\Python\Python312\Lib\http\client.py", line 1365, in _send_request
    self.endheaders(body, encode_chunked=encode_chunked)
  File "C:\Users\张洛\AppData\Local\Programs\Python\Python312\Lib\http\client.py", line 1314, in endheaders
    self._send_output(message_body, encode_chunked=encode_chunked)
  File "C:\Users\张洛\AppData\Local\Programs\Python\Python312\Lib\http\client.py", line 1074, in _send_output
    self.send(msg)
  File "C:\Users\张洛\AppData\Local\Programs\Python\Python312\Lib\http\client.py", line 1018, in send
    self.connect()
  File "C:\robot_work\.venv\Lib\site-packages\urllib3\connection.py", line 205, in connect
    conn = self._new_conn()
           ^^^^^^^^^^^^^^^^
  File "C:\robot_work\.venv\Lib\site-packages\urllib3\connection.py", line 186, in _new_conn
    raise NewConnectionError(
urllib3.exceptions.NewConnectionError: <urllib3.connection.HTTPConnection object at 0x0000016953D126F0>: Failed to establish a new connection: [WinError 10061] 由于目标计算机积极拒绝，无法连接。

During handling of the above exception, another exception occurred:

Traceback (most recent call last):
  File "C:\robot_work\.venv\Lib\site-packages\requests\adapters.py", line 667, in send
    resp = conn.urlopen(
           ^^^^^^^^^^^^^
  File "C:\robot_work\.venv\Lib\site-packages\urllib3\connectionpool.py", line 802, in urlopen
    retries = retries.increment(
              ^^^^^^^^^^^^^^^^^^
  File "C:\robot_work\.venv\Lib\site-packages\urllib3\util\retry.py", line 594, in increment
    raise MaxRetryError(_pool, url, error or ResponseError(cause))
urllib3.exceptions.MaxRetryError: HTTPConnectionPool(host='localhost', port=6800): Max retries exceeded with url: /listjobs.json?project=robot_work (Caused by NewConnectionError('<urllib3.connection.HTTPConnection object at 0x0000016953D126F0>: Failed to establish a new connection: [WinError 10061] 由于目标计算机积极拒绝，无法连接。'))

During handling of the above exception, another exception occurred:

Traceback (most recent call last):
  File "C:\robot_work\.venv\Lib\site-packages\gerapy\server\core\utils.py", line 562, in wrapper
    result = func(*args, **kwargs)
             ^^^^^^^^^^^^^^^^^^^^^
  File "C:\robot_work\.venv\Lib\site-packages\django\views\decorators\csrf.py", line 54, in wrapped_view
    return view_func(*args, **kwargs)
           ^^^^^^^^^^^^^^^^^^^^^^^^^^
  File "C:\robot_work\.venv\Lib\site-packages\django\views\generic\base.py", line 71, in view
    return self.dispatch(request, *args, **kwargs)
           ^^^^^^^^^^^^^^^^^^^^^^^^^^^^^^^^^^^^^^^
  File "C:\robot_work\.venv\Lib\site-packages\rest_framework\views.py", line 509, in dispatch
    response = self.handle_exception(exc)
               ^^^^^^^^^^^^^^^^^^^^^^^^^^
  File "C:\robot_work\.venv\Lib\site-packages\rest_framework\views.py", line 469, in handle_exception
    self.raise_uncaught_exception(exc)
  File "C:\robot_work\.venv\Lib\site-packages\rest_framework\views.py", line 480, in raise_uncaught_exception
    raise exc
  File "C:\robot_work\.venv\Lib\site-packages\rest_framework\views.py", line 506, in dispatch
    response = handler(request, *args, **kwargs)
               ^^^^^^^^^^^^^^^^^^^^^^^^^^^^^^^^^
  File "C:\robot_work\.venv\Lib\site-packages\rest_framework\decorators.py", line 50, in handler
    return func(*args, **kwargs)
           ^^^^^^^^^^^^^^^^^^^^^
  File "C:\robot_work\.venv\Lib\site-packages\gerapy\server\core\views.py", line 690, in job_list
    result = scrapyd.list_jobs(project_name)
             ^^^^^^^^^^^^^^^^^^^^^^^^^^^^^^^
  File "C:\robot_work\.venv\Lib\site-packages\scrapyd_api\wrapper.py", line 139, in list_jobs
    jobs = self.client.get(url, params=params, timeout=self.timeout)
           ^^^^^^^^^^^^^^^^^^^^^^^^^^^^^^^^^^^^^^^^^^^^^^^^^^^^^^^^^
  File "C:\robot_work\.venv\Lib\site-packages\requests\sessions.py", line 602, in get
    return self.request("GET", url, **kwargs)
           ^^^^^^^^^^^^^^^^^^^^^^^^^^^^^^^^^^
  File "C:\robot_work\.venv\Lib\site-packages\scrapyd_api\client.py", line 37, in request
    response = super(Client, self).request(*args, **kwargs)
               ^^^^^^^^^^^^^^^^^^^^^^^^^^^^^^^^^^^^^^^^^^^^
  File "C:\robot_work\.venv\Lib\site-packages\requests\sessions.py", line 589, in request
    resp = self.send(prep, **send_kwargs)
           ^^^^^^^^^^^^^^^^^^^^^^^^^^^^^^
  File "C:\robot_work\.venv\Lib\site-packages\requests\sessions.py", line 703, in send
    r = adapter.send(request, **kwargs)
        ^^^^^^^^^^^^^^^^^^^^^^^^^^^^^^^
  File "C:\robot_work\.venv\Lib\site-packages\requests\adapters.py", line 700, in send
    raise ConnectionError(e, request=request)
requests.exceptions.ConnectionError: HTTPConnectionPool(host='localhost', port=6800): Max retries exceeded with url: /listjobs.json?project=robot_work (Caused by NewConnectionError('<urllib3.connection.HTTPConnection object at 0x0000016953D126F0>: Failed to establish a new connection: [WinError 10061] 由于目标计算机积极拒绝，无法连接。'))
ERROR - 2024-11-11 18:12:52,108 - process: 8332 - utils.py - gerapy.server.core.utils - 564 - utils - ('Connection aborted.', RemoteDisconnected('Remote end closed connection without response'))
Traceback (most recent call last):
  File "C:\robot_work\.venv\Lib\site-packages\urllib3\connectionpool.py", line 716, in urlopen
    httplib_response = self._make_request(
                       ^^^^^^^^^^^^^^^^^^^
  File "C:\robot_work\.venv\Lib\site-packages\urllib3\connectionpool.py", line 468, in _make_request
    six.raise_from(e, None)
  File "<string>", line 3, in raise_from
  File "C:\robot_work\.venv\Lib\site-packages\urllib3\connectionpool.py", line 463, in _make_request
    httplib_response = conn.getresponse()
                       ^^^^^^^^^^^^^^^^^^
  File "C:\Users\张洛\AppData\Local\Programs\Python\Python312\Lib\http\client.py", line 1411, in getresponse
    response.begin()
  File "C:\Users\张洛\AppData\Local\Programs\Python\Python312\Lib\http\client.py", line 324, in begin
    version, status, reason = self._read_status()
                              ^^^^^^^^^^^^^^^^^^^
  File "C:\Users\张洛\AppData\Local\Programs\Python\Python312\Lib\http\client.py", line 293, in _read_status
    raise RemoteDisconnected("Remote end closed connection without"
http.client.RemoteDisconnected: Remote end closed connection without response

During handling of the above exception, another exception occurred:

Traceback (most recent call last):
  File "C:\robot_work\.venv\Lib\site-packages\requests\adapters.py", line 667, in send
    resp = conn.urlopen(
           ^^^^^^^^^^^^^
  File "C:\robot_work\.venv\Lib\site-packages\urllib3\connectionpool.py", line 802, in urlopen
    retries = retries.increment(
              ^^^^^^^^^^^^^^^^^^
  File "C:\robot_work\.venv\Lib\site-packages\urllib3\util\retry.py", line 552, in increment
    raise six.reraise(type(error), error, _stacktrace)
          ^^^^^^^^^^^^^^^^^^^^^^^^^^^^^^^^^^^^^^^^^^^^
  File "C:\robot_work\.venv\Lib\site-packages\urllib3\packages\six.py", line 769, in reraise
    raise value.with_traceback(tb)
  File "C:\robot_work\.venv\Lib\site-packages\urllib3\connectionpool.py", line 716, in urlopen
    httplib_response = self._make_request(
                       ^^^^^^^^^^^^^^^^^^^
  File "C:\robot_work\.venv\Lib\site-packages\urllib3\connectionpool.py", line 468, in _make_request
    six.raise_from(e, None)
  File "<string>", line 3, in raise_from
  File "C:\robot_work\.venv\Lib\site-packages\urllib3\connectionpool.py", line 463, in _make_request
    httplib_response = conn.getresponse()
                       ^^^^^^^^^^^^^^^^^^
  File "C:\Users\张洛\AppData\Local\Programs\Python\Python312\Lib\http\client.py", line 1411, in getresponse
    response.begin()
  File "C:\Users\张洛\AppData\Local\Programs\Python\Python312\Lib\http\client.py", line 324, in begin
    version, status, reason = self._read_status()
                              ^^^^^^^^^^^^^^^^^^^
  File "C:\Users\张洛\AppData\Local\Programs\Python\Python312\Lib\http\client.py", line 293, in _read_status
    raise RemoteDisconnected("Remote end closed connection without"
urllib3.exceptions.ProtocolError: ('Connection aborted.', RemoteDisconnected('Remote end closed connection without response'))

During handling of the above exception, another exception occurred:

Traceback (most recent call last):
  File "C:\robot_work\.venv\Lib\site-packages\gerapy\server\core\utils.py", line 562, in wrapper
    result = func(*args, **kwargs)
             ^^^^^^^^^^^^^^^^^^^^^
  File "C:\robot_work\.venv\Lib\site-packages\django\views\decorators\csrf.py", line 54, in wrapped_view
    return view_func(*args, **kwargs)
           ^^^^^^^^^^^^^^^^^^^^^^^^^^
  File "C:\robot_work\.venv\Lib\site-packages\django\views\generic\base.py", line 71, in view
    return self.dispatch(request, *args, **kwargs)
           ^^^^^^^^^^^^^^^^^^^^^^^^^^^^^^^^^^^^^^^
  File "C:\robot_work\.venv\Lib\site-packages\rest_framework\views.py", line 509, in dispatch
    response = self.handle_exception(exc)
               ^^^^^^^^^^^^^^^^^^^^^^^^^^
  File "C:\robot_work\.venv\Lib\site-packages\rest_framework\views.py", line 469, in handle_exception
    self.raise_uncaught_exception(exc)
  File "C:\robot_work\.venv\Lib\site-packages\rest_framework\views.py", line 480, in raise_uncaught_exception
    raise exc
  File "C:\robot_work\.venv\Lib\site-packages\rest_framework\views.py", line 506, in dispatch
    response = handler(request, *args, **kwargs)
               ^^^^^^^^^^^^^^^^^^^^^^^^^^^^^^^^^
  File "C:\robot_work\.venv\Lib\site-packages\rest_framework\decorators.py", line 50, in handler
    return func(*args, **kwargs)
           ^^^^^^^^^^^^^^^^^^^^^
  File "C:\robot_work\.venv\Lib\site-packages\gerapy\server\core\views.py", line 690, in job_list
    result = scrapyd.list_jobs(project_name)
             ^^^^^^^^^^^^^^^^^^^^^^^^^^^^^^^
  File "C:\robot_work\.venv\Lib\site-packages\scrapyd_api\wrapper.py", line 139, in list_jobs
    jobs = self.client.get(url, params=params, timeout=self.timeout)
           ^^^^^^^^^^^^^^^^^^^^^^^^^^^^^^^^^^^^^^^^^^^^^^^^^^^^^^^^^
  File "C:\robot_work\.venv\Lib\site-packages\requests\sessions.py", line 602, in get
    return self.request("GET", url, **kwargs)
           ^^^^^^^^^^^^^^^^^^^^^^^^^^^^^^^^^^
  File "C:\robot_work\.venv\Lib\site-packages\scrapyd_api\client.py", line 37, in request
    response = super(Client, self).request(*args, **kwargs)
               ^^^^^^^^^^^^^^^^^^^^^^^^^^^^^^^^^^^^^^^^^^^^
  File "C:\robot_work\.venv\Lib\site-packages\requests\sessions.py", line 589, in request
    resp = self.send(prep, **send_kwargs)
           ^^^^^^^^^^^^^^^^^^^^^^^^^^^^^^
  File "C:\robot_work\.venv\Lib\site-packages\requests\sessions.py", line 703, in send
    r = adapter.send(request, **kwargs)
        ^^^^^^^^^^^^^^^^^^^^^^^^^^^^^^^
  File "C:\robot_work\.venv\Lib\site-packages\requests\adapters.py", line 682, in send
    raise ConnectionError(err, request=request)
requests.exceptions.ConnectionError: ('Connection aborted.', RemoteDisconnected('Remote end closed connection without response'))
ERROR - 2024-11-11 18:18:22,459 - process: 8332 - utils.py - gerapy.server.core.utils - 564 - utils - [WinError 3] 系统找不到指定的路径。: 'C:\\robot_work\\projects'
Traceback (most recent call last):
  File "C:\robot_work\.venv\Lib\site-packages\gerapy\server\core\utils.py", line 562, in wrapper
    result = func(*args, **kwargs)
             ^^^^^^^^^^^^^^^^^^^^^
  File "C:\robot_work\.venv\Lib\site-packages\django\views\decorators\csrf.py", line 54, in wrapped_view
    return view_func(*args, **kwargs)
           ^^^^^^^^^^^^^^^^^^^^^^^^^^
  File "C:\robot_work\.venv\Lib\site-packages\django\views\generic\base.py", line 71, in view
    return self.dispatch(request, *args, **kwargs)
           ^^^^^^^^^^^^^^^^^^^^^^^^^^^^^^^^^^^^^^^
  File "C:\robot_work\.venv\Lib\site-packages\rest_framework\views.py", line 509, in dispatch
    response = self.handle_exception(exc)
               ^^^^^^^^^^^^^^^^^^^^^^^^^^
  File "C:\robot_work\.venv\Lib\site-packages\rest_framework\views.py", line 469, in handle_exception
    self.raise_uncaught_exception(exc)
  File "C:\robot_work\.venv\Lib\site-packages\rest_framework\views.py", line 480, in raise_uncaught_exception
    raise exc
  File "C:\robot_work\.venv\Lib\site-packages\rest_framework\views.py", line 506, in dispatch
    response = handler(request, *args, **kwargs)
               ^^^^^^^^^^^^^^^^^^^^^^^^^^^^^^^^^
  File "C:\robot_work\.venv\Lib\site-packages\rest_framework\decorators.py", line 50, in handler
    return func(*args, **kwargs)
           ^^^^^^^^^^^^^^^^^^^^^
  File "C:\robot_work\.venv\Lib\site-packages\gerapy\server\core\views.py", line 242, in project_index
    files = os.listdir(path)
            ^^^^^^^^^^^^^^^^
FileNotFoundError: [WinError 3] 系统找不到指定的路径。: 'C:\\robot_work\\projects'
ERROR - 2024-11-11 18:18:23,373 - process: 8332 - utils.py - gerapy.server.core.utils - 564 - utils - [WinError 3] 系统找不到指定的路径。: 'C:\\robot_work\\projects'
Traceback (most recent call last):
  File "C:\robot_work\.venv\Lib\site-packages\gerapy\server\core\utils.py", line 562, in wrapper
    result = func(*args, **kwargs)
             ^^^^^^^^^^^^^^^^^^^^^
  File "C:\robot_work\.venv\Lib\site-packages\django\views\decorators\csrf.py", line 54, in wrapped_view
    return view_func(*args, **kwargs)
           ^^^^^^^^^^^^^^^^^^^^^^^^^^
  File "C:\robot_work\.venv\Lib\site-packages\django\views\generic\base.py", line 71, in view
    return self.dispatch(request, *args, **kwargs)
           ^^^^^^^^^^^^^^^^^^^^^^^^^^^^^^^^^^^^^^^
  File "C:\robot_work\.venv\Lib\site-packages\rest_framework\views.py", line 509, in dispatch
    response = self.handle_exception(exc)
               ^^^^^^^^^^^^^^^^^^^^^^^^^^
  File "C:\robot_work\.venv\Lib\site-packages\rest_framework\views.py", line 469, in handle_exception
    self.raise_uncaught_exception(exc)
  File "C:\robot_work\.venv\Lib\site-packages\rest_framework\views.py", line 480, in raise_uncaught_exception
    raise exc
  File "C:\robot_work\.venv\Lib\site-packages\rest_framework\views.py", line 506, in dispatch
    response = handler(request, *args, **kwargs)
               ^^^^^^^^^^^^^^^^^^^^^^^^^^^^^^^^^
  File "C:\robot_work\.venv\Lib\site-packages\rest_framework\decorators.py", line 50, in handler
    return func(*args, **kwargs)
           ^^^^^^^^^^^^^^^^^^^^^
  File "C:\robot_work\.venv\Lib\site-packages\gerapy\server\core\views.py", line 242, in project_index
    files = os.listdir(path)
            ^^^^^^^^^^^^^^^^
FileNotFoundError: [WinError 3] 系统找不到指定的路径。: 'C:\\robot_work\\projects'
ERROR - 2024-11-11 19:12:54,132 - process: 8332 - utils.py - gerapy.server.core.utils - 564 - utils - HTTPConnectionPool(host='10.34.29.44', port=6800): Max retries exceeded with url: / (Caused by ConnectTimeoutError(<urllib3.connection.HTTPConnection object at 0x0000016953D132C0>, 'Connection to 10.34.29.44 timed out. (connect timeout=3)'))
Traceback (most recent call last):
  File "C:\robot_work\.venv\Lib\site-packages\urllib3\connection.py", line 174, in _new_conn
    conn = connection.create_connection(
           ^^^^^^^^^^^^^^^^^^^^^^^^^^^^^
  File "C:\robot_work\.venv\Lib\site-packages\urllib3\util\connection.py", line 95, in create_connection
    raise err
  File "C:\robot_work\.venv\Lib\site-packages\urllib3\util\connection.py", line 85, in create_connection
    sock.connect(sa)
TimeoutError: timed out

During handling of the above exception, another exception occurred:

Traceback (most recent call last):
  File "C:\robot_work\.venv\Lib\site-packages\urllib3\connectionpool.py", line 716, in urlopen
    httplib_response = self._make_request(
                       ^^^^^^^^^^^^^^^^^^^
  File "C:\robot_work\.venv\Lib\site-packages\urllib3\connectionpool.py", line 416, in _make_request
    conn.request(method, url, **httplib_request_kw)
  File "C:\robot_work\.venv\Lib\site-packages\urllib3\connection.py", line 244, in request
    super(HTTPConnection, self).request(method, url, body=body, headers=headers)
  File "C:\Users\张洛\AppData\Local\Programs\Python\Python312\Lib\http\client.py", line 1319, in request
    self._send_request(method, url, body, headers, encode_chunked)
  File "C:\Users\张洛\AppData\Local\Programs\Python\Python312\Lib\http\client.py", line 1365, in _send_request
    self.endheaders(body, encode_chunked=encode_chunked)
  File "C:\Users\张洛\AppData\Local\Programs\Python\Python312\Lib\http\client.py", line 1314, in endheaders
    self._send_output(message_body, encode_chunked=encode_chunked)
  File "C:\Users\张洛\AppData\Local\Programs\Python\Python312\Lib\http\client.py", line 1074, in _send_output
    self.send(msg)
  File "C:\Users\张洛\AppData\Local\Programs\Python\Python312\Lib\http\client.py", line 1018, in send
    self.connect()
  File "C:\robot_work\.venv\Lib\site-packages\urllib3\connection.py", line 205, in connect
    conn = self._new_conn()
           ^^^^^^^^^^^^^^^^
  File "C:\robot_work\.venv\Lib\site-packages\urllib3\connection.py", line 179, in _new_conn
    raise ConnectTimeoutError(
urllib3.exceptions.ConnectTimeoutError: (<urllib3.connection.HTTPConnection object at 0x0000016953D132C0>, 'Connection to 10.34.29.44 timed out. (connect timeout=3)')

During handling of the above exception, another exception occurred:

Traceback (most recent call last):
  File "C:\robot_work\.venv\Lib\site-packages\requests\adapters.py", line 667, in send
    resp = conn.urlopen(
           ^^^^^^^^^^^^^
  File "C:\robot_work\.venv\Lib\site-packages\urllib3\connectionpool.py", line 802, in urlopen
    retries = retries.increment(
              ^^^^^^^^^^^^^^^^^^
  File "C:\robot_work\.venv\Lib\site-packages\urllib3\util\retry.py", line 594, in increment
    raise MaxRetryError(_pool, url, error or ResponseError(cause))
urllib3.exceptions.MaxRetryError: HTTPConnectionPool(host='10.34.29.44', port=6800): Max retries exceeded with url: / (Caused by ConnectTimeoutError(<urllib3.connection.HTTPConnection object at 0x0000016953D132C0>, 'Connection to 10.34.29.44 timed out. (connect timeout=3)'))

During handling of the above exception, another exception occurred:

Traceback (most recent call last):
  File "C:\robot_work\.venv\Lib\site-packages\gerapy\server\core\utils.py", line 562, in wrapper
    result = func(*args, **kwargs)
             ^^^^^^^^^^^^^^^^^^^^^
  File "C:\robot_work\.venv\Lib\site-packages\django\views\decorators\csrf.py", line 54, in wrapped_view
    return view_func(*args, **kwargs)
           ^^^^^^^^^^^^^^^^^^^^^^^^^^
  File "C:\robot_work\.venv\Lib\site-packages\django\views\generic\base.py", line 71, in view
    return self.dispatch(request, *args, **kwargs)
           ^^^^^^^^^^^^^^^^^^^^^^^^^^^^^^^^^^^^^^^
  File "C:\robot_work\.venv\Lib\site-packages\rest_framework\views.py", line 509, in dispatch
    response = self.handle_exception(exc)
               ^^^^^^^^^^^^^^^^^^^^^^^^^^
  File "C:\robot_work\.venv\Lib\site-packages\rest_framework\views.py", line 469, in handle_exception
    self.raise_uncaught_exception(exc)
  File "C:\robot_work\.venv\Lib\site-packages\rest_framework\views.py", line 480, in raise_uncaught_exception
    raise exc
  File "C:\robot_work\.venv\Lib\site-packages\rest_framework\views.py", line 506, in dispatch
    response = handler(request, *args, **kwargs)
               ^^^^^^^^^^^^^^^^^^^^^^^^^^^^^^^^^
  File "C:\robot_work\.venv\Lib\site-packages\rest_framework\decorators.py", line 50, in handler
    return func(*args, **kwargs)
           ^^^^^^^^^^^^^^^^^^^^^
  File "C:\robot_work\.venv\Lib\site-packages\gerapy\server\core\views.py", line 120, in client_status
    requests.get(scrapyd_url(client.ip, client.port), timeout=3)
  File "C:\robot_work\.venv\Lib\site-packages\requests\api.py", line 73, in get
    return request("get", url, params=params, **kwargs)
           ^^^^^^^^^^^^^^^^^^^^^^^^^^^^^^^^^^^^^^^^^^^^
  File "C:\robot_work\.venv\Lib\site-packages\requests\api.py", line 59, in request
    return session.request(method=method, url=url, **kwargs)
           ^^^^^^^^^^^^^^^^^^^^^^^^^^^^^^^^^^^^^^^^^^^^^^^^^
  File "C:\robot_work\.venv\Lib\site-packages\requests\sessions.py", line 589, in request
    resp = self.send(prep, **send_kwargs)
           ^^^^^^^^^^^^^^^^^^^^^^^^^^^^^^
  File "C:\robot_work\.venv\Lib\site-packages\requests\sessions.py", line 703, in send
    r = adapter.send(request, **kwargs)
        ^^^^^^^^^^^^^^^^^^^^^^^^^^^^^^^
  File "C:\robot_work\.venv\Lib\site-packages\requests\adapters.py", line 688, in send
    raise ConnectTimeout(e, request=request)
requests.exceptions.ConnectTimeout: HTTPConnectionPool(host='10.34.29.44', port=6800): Max retries exceeded with url: / (Caused by ConnectTimeoutError(<urllib3.connection.HTTPConnection object at 0x0000016953D132C0>, 'Connection to 10.34.29.44 timed out. (connect timeout=3)'))
ERROR - 2024-11-11 19:12:55,518 - process: 8332 - utils.py - gerapy.server.core.utils - 564 - utils - HTTPConnectionPool(host='10.34.29.44', port=6800): Max retries exceeded with url: / (Caused by ConnectTimeoutError(<urllib3.connection.HTTPConnection object at 0x0000016953A64AD0>, 'Connection to 10.34.29.44 timed out. (connect timeout=3)'))
Traceback (most recent call last):
  File "C:\robot_work\.venv\Lib\site-packages\urllib3\connection.py", line 174, in _new_conn
    conn = connection.create_connection(
           ^^^^^^^^^^^^^^^^^^^^^^^^^^^^^
  File "C:\robot_work\.venv\Lib\site-packages\urllib3\util\connection.py", line 95, in create_connection
    raise err
  File "C:\robot_work\.venv\Lib\site-packages\urllib3\util\connection.py", line 85, in create_connection
    sock.connect(sa)
TimeoutError: timed out

During handling of the above exception, another exception occurred:

Traceback (most recent call last):
  File "C:\robot_work\.venv\Lib\site-packages\urllib3\connectionpool.py", line 716, in urlopen
    httplib_response = self._make_request(
                       ^^^^^^^^^^^^^^^^^^^
  File "C:\robot_work\.venv\Lib\site-packages\urllib3\connectionpool.py", line 416, in _make_request
    conn.request(method, url, **httplib_request_kw)
  File "C:\robot_work\.venv\Lib\site-packages\urllib3\connection.py", line 244, in request
    super(HTTPConnection, self).request(method, url, body=body, headers=headers)
  File "C:\Users\张洛\AppData\Local\Programs\Python\Python312\Lib\http\client.py", line 1319, in request
    self._send_request(method, url, body, headers, encode_chunked)
  File "C:\Users\张洛\AppData\Local\Programs\Python\Python312\Lib\http\client.py", line 1365, in _send_request
    self.endheaders(body, encode_chunked=encode_chunked)
  File "C:\Users\张洛\AppData\Local\Programs\Python\Python312\Lib\http\client.py", line 1314, in endheaders
    self._send_output(message_body, encode_chunked=encode_chunked)
  File "C:\Users\张洛\AppData\Local\Programs\Python\Python312\Lib\http\client.py", line 1074, in _send_output
    self.send(msg)
  File "C:\Users\张洛\AppData\Local\Programs\Python\Python312\Lib\http\client.py", line 1018, in send
    self.connect()
  File "C:\robot_work\.venv\Lib\site-packages\urllib3\connection.py", line 205, in connect
    conn = self._new_conn()
           ^^^^^^^^^^^^^^^^
  File "C:\robot_work\.venv\Lib\site-packages\urllib3\connection.py", line 179, in _new_conn
    raise ConnectTimeoutError(
urllib3.exceptions.ConnectTimeoutError: (<urllib3.connection.HTTPConnection object at 0x0000016953A64AD0>, 'Connection to 10.34.29.44 timed out. (connect timeout=3)')

During handling of the above exception, another exception occurred:

Traceback (most recent call last):
  File "C:\robot_work\.venv\Lib\site-packages\requests\adapters.py", line 667, in send
    resp = conn.urlopen(
           ^^^^^^^^^^^^^
  File "C:\robot_work\.venv\Lib\site-packages\urllib3\connectionpool.py", line 802, in urlopen
    retries = retries.increment(
              ^^^^^^^^^^^^^^^^^^
  File "C:\robot_work\.venv\Lib\site-packages\urllib3\util\retry.py", line 594, in increment
    raise MaxRetryError(_pool, url, error or ResponseError(cause))
urllib3.exceptions.MaxRetryError: HTTPConnectionPool(host='10.34.29.44', port=6800): Max retries exceeded with url: / (Caused by ConnectTimeoutError(<urllib3.connection.HTTPConnection object at 0x0000016953A64AD0>, 'Connection to 10.34.29.44 timed out. (connect timeout=3)'))

During handling of the above exception, another exception occurred:

Traceback (most recent call last):
  File "C:\robot_work\.venv\Lib\site-packages\gerapy\server\core\utils.py", line 562, in wrapper
    result = func(*args, **kwargs)
             ^^^^^^^^^^^^^^^^^^^^^
  File "C:\robot_work\.venv\Lib\site-packages\django\views\decorators\csrf.py", line 54, in wrapped_view
    return view_func(*args, **kwargs)
           ^^^^^^^^^^^^^^^^^^^^^^^^^^
  File "C:\robot_work\.venv\Lib\site-packages\django\views\generic\base.py", line 71, in view
    return self.dispatch(request, *args, **kwargs)
           ^^^^^^^^^^^^^^^^^^^^^^^^^^^^^^^^^^^^^^^
  File "C:\robot_work\.venv\Lib\site-packages\rest_framework\views.py", line 509, in dispatch
    response = self.handle_exception(exc)
               ^^^^^^^^^^^^^^^^^^^^^^^^^^
  File "C:\robot_work\.venv\Lib\site-packages\rest_framework\views.py", line 469, in handle_exception
    self.raise_uncaught_exception(exc)
  File "C:\robot_work\.venv\Lib\site-packages\rest_framework\views.py", line 480, in raise_uncaught_exception
    raise exc
  File "C:\robot_work\.venv\Lib\site-packages\rest_framework\views.py", line 506, in dispatch
    response = handler(request, *args, **kwargs)
               ^^^^^^^^^^^^^^^^^^^^^^^^^^^^^^^^^
  File "C:\robot_work\.venv\Lib\site-packages\rest_framework\decorators.py", line 50, in handler
    return func(*args, **kwargs)
           ^^^^^^^^^^^^^^^^^^^^^
  File "C:\robot_work\.venv\Lib\site-packages\gerapy\server\core\views.py", line 120, in client_status
    requests.get(scrapyd_url(client.ip, client.port), timeout=3)
  File "C:\robot_work\.venv\Lib\site-packages\requests\api.py", line 73, in get
    return request("get", url, params=params, **kwargs)
           ^^^^^^^^^^^^^^^^^^^^^^^^^^^^^^^^^^^^^^^^^^^^
  File "C:\robot_work\.venv\Lib\site-packages\requests\api.py", line 59, in request
    return session.request(method=method, url=url, **kwargs)
           ^^^^^^^^^^^^^^^^^^^^^^^^^^^^^^^^^^^^^^^^^^^^^^^^^
  File "C:\robot_work\.venv\Lib\site-packages\requests\sessions.py", line 589, in request
    resp = self.send(prep, **send_kwargs)
           ^^^^^^^^^^^^^^^^^^^^^^^^^^^^^^
  File "C:\robot_work\.venv\Lib\site-packages\requests\sessions.py", line 703, in send
    r = adapter.send(request, **kwargs)
        ^^^^^^^^^^^^^^^^^^^^^^^^^^^^^^^
  File "C:\robot_work\.venv\Lib\site-packages\requests\adapters.py", line 688, in send
    raise ConnectTimeout(e, request=request)
requests.exceptions.ConnectTimeout: HTTPConnectionPool(host='10.34.29.44', port=6800): Max retries exceeded with url: / (Caused by ConnectTimeoutError(<urllib3.connection.HTTPConnection object at 0x0000016953A64AD0>, 'Connection to 10.34.29.44 timed out. (connect timeout=3)'))
ERROR - 2024-11-11 19:13:55,132 - process: 8332 - utils.py - gerapy.server.core.utils - 564 - utils - HTTPConnectionPool(host='10.33.25.336', port=6800): Max retries exceeded with url: / (Caused by NewConnectionError('<urllib3.connection.HTTPConnection object at 0x0000016953D11700>: Failed to establish a new connection: [Errno 11001] getaddrinfo failed'))
Traceback (most recent call last):
  File "C:\robot_work\.venv\Lib\site-packages\urllib3\connection.py", line 174, in _new_conn
    conn = connection.create_connection(
           ^^^^^^^^^^^^^^^^^^^^^^^^^^^^^
  File "C:\robot_work\.venv\Lib\site-packages\urllib3\util\connection.py", line 72, in create_connection
    for res in socket.getaddrinfo(host, port, family, socket.SOCK_STREAM):
               ^^^^^^^^^^^^^^^^^^^^^^^^^^^^^^^^^^^^^^^^^^^^^^^^^^^^^^^^^^
  File "C:\Users\张洛\AppData\Local\Programs\Python\Python312\Lib\socket.py", line 963, in getaddrinfo
    for res in _socket.getaddrinfo(host, port, family, type, proto, flags):
               ^^^^^^^^^^^^^^^^^^^^^^^^^^^^^^^^^^^^^^^^^^^^^^^^^^^^^^^^^^^
socket.gaierror: [Errno 11001] getaddrinfo failed

During handling of the above exception, another exception occurred:

Traceback (most recent call last):
  File "C:\robot_work\.venv\Lib\site-packages\urllib3\connectionpool.py", line 716, in urlopen
    httplib_response = self._make_request(
                       ^^^^^^^^^^^^^^^^^^^
  File "C:\robot_work\.venv\Lib\site-packages\urllib3\connectionpool.py", line 416, in _make_request
    conn.request(method, url, **httplib_request_kw)
  File "C:\robot_work\.venv\Lib\site-packages\urllib3\connection.py", line 244, in request
    super(HTTPConnection, self).request(method, url, body=body, headers=headers)
  File "C:\Users\张洛\AppData\Local\Programs\Python\Python312\Lib\http\client.py", line 1319, in request
    self._send_request(method, url, body, headers, encode_chunked)
  File "C:\Users\张洛\AppData\Local\Programs\Python\Python312\Lib\http\client.py", line 1365, in _send_request
    self.endheaders(body, encode_chunked=encode_chunked)
  File "C:\Users\张洛\AppData\Local\Programs\Python\Python312\Lib\http\client.py", line 1314, in endheaders
    self._send_output(message_body, encode_chunked=encode_chunked)
  File "C:\Users\张洛\AppData\Local\Programs\Python\Python312\Lib\http\client.py", line 1074, in _send_output
    self.send(msg)
  File "C:\Users\张洛\AppData\Local\Programs\Python\Python312\Lib\http\client.py", line 1018, in send
    self.connect()
  File "C:\robot_work\.venv\Lib\site-packages\urllib3\connection.py", line 205, in connect
    conn = self._new_conn()
           ^^^^^^^^^^^^^^^^
  File "C:\robot_work\.venv\Lib\site-packages\urllib3\connection.py", line 186, in _new_conn
    raise NewConnectionError(
urllib3.exceptions.NewConnectionError: <urllib3.connection.HTTPConnection object at 0x0000016953D11700>: Failed to establish a new connection: [Errno 11001] getaddrinfo failed

During handling of the above exception, another exception occurred:

Traceback (most recent call last):
  File "C:\robot_work\.venv\Lib\site-packages\requests\adapters.py", line 667, in send
    resp = conn.urlopen(
           ^^^^^^^^^^^^^
  File "C:\robot_work\.venv\Lib\site-packages\urllib3\connectionpool.py", line 802, in urlopen
    retries = retries.increment(
              ^^^^^^^^^^^^^^^^^^
  File "C:\robot_work\.venv\Lib\site-packages\urllib3\util\retry.py", line 594, in increment
    raise MaxRetryError(_pool, url, error or ResponseError(cause))
urllib3.exceptions.MaxRetryError: HTTPConnectionPool(host='10.33.25.336', port=6800): Max retries exceeded with url: / (Caused by NewConnectionError('<urllib3.connection.HTTPConnection object at 0x0000016953D11700>: Failed to establish a new connection: [Errno 11001] getaddrinfo failed'))

During handling of the above exception, another exception occurred:

Traceback (most recent call last):
  File "C:\robot_work\.venv\Lib\site-packages\gerapy\server\core\utils.py", line 562, in wrapper
    result = func(*args, **kwargs)
             ^^^^^^^^^^^^^^^^^^^^^
  File "C:\robot_work\.venv\Lib\site-packages\django\views\decorators\csrf.py", line 54, in wrapped_view
    return view_func(*args, **kwargs)
           ^^^^^^^^^^^^^^^^^^^^^^^^^^
  File "C:\robot_work\.venv\Lib\site-packages\django\views\generic\base.py", line 71, in view
    return self.dispatch(request, *args, **kwargs)
           ^^^^^^^^^^^^^^^^^^^^^^^^^^^^^^^^^^^^^^^
  File "C:\robot_work\.venv\Lib\site-packages\rest_framework\views.py", line 509, in dispatch
    response = self.handle_exception(exc)
               ^^^^^^^^^^^^^^^^^^^^^^^^^^
  File "C:\robot_work\.venv\Lib\site-packages\rest_framework\views.py", line 469, in handle_exception
    self.raise_uncaught_exception(exc)
  File "C:\robot_work\.venv\Lib\site-packages\rest_framework\views.py", line 480, in raise_uncaught_exception
    raise exc
  File "C:\robot_work\.venv\Lib\site-packages\rest_framework\views.py", line 506, in dispatch
    response = handler(request, *args, **kwargs)
               ^^^^^^^^^^^^^^^^^^^^^^^^^^^^^^^^^
  File "C:\robot_work\.venv\Lib\site-packages\rest_framework\decorators.py", line 50, in handler
    return func(*args, **kwargs)
           ^^^^^^^^^^^^^^^^^^^^^
  File "C:\robot_work\.venv\Lib\site-packages\gerapy\server\core\views.py", line 120, in client_status
    requests.get(scrapyd_url(client.ip, client.port), timeout=3)
  File "C:\robot_work\.venv\Lib\site-packages\requests\api.py", line 73, in get
    return request("get", url, params=params, **kwargs)
           ^^^^^^^^^^^^^^^^^^^^^^^^^^^^^^^^^^^^^^^^^^^^
  File "C:\robot_work\.venv\Lib\site-packages\requests\api.py", line 59, in request
    return session.request(method=method, url=url, **kwargs)
           ^^^^^^^^^^^^^^^^^^^^^^^^^^^^^^^^^^^^^^^^^^^^^^^^^
  File "C:\robot_work\.venv\Lib\site-packages\requests\sessions.py", line 589, in request
    resp = self.send(prep, **send_kwargs)
           ^^^^^^^^^^^^^^^^^^^^^^^^^^^^^^
  File "C:\robot_work\.venv\Lib\site-packages\requests\sessions.py", line 703, in send
    r = adapter.send(request, **kwargs)
        ^^^^^^^^^^^^^^^^^^^^^^^^^^^^^^^
  File "C:\robot_work\.venv\Lib\site-packages\requests\adapters.py", line 700, in send
    raise ConnectionError(e, request=request)
requests.exceptions.ConnectionError: HTTPConnectionPool(host='10.33.25.336', port=6800): Max retries exceeded with url: / (Caused by NewConnectionError('<urllib3.connection.HTTPConnection object at 0x0000016953D11700>: Failed to establish a new connection: [Errno 11001] getaddrinfo failed'))
