INFO - 2024-11-10 21:48:20,121 - process: 6576 - scheduler.py - gerapy.server.core.scheduler - 105 - scheduler - successfully synced task with jobs with force
ERROR - 2024-11-10 21:48:31,097 - process: 6576 - utils.py - gerapy.server.core.utils - 564 - utils - [WinError 3] 系统找不到指定的路径。: 'C:\\robot_work\\projects'
Traceback (most recent call last):
  File "C:\robot_work\.venv\Lib\site-packages\gerapy\server\core\utils.py", line 562, in wrapper
    result = func(*args, **kwargs)
             ^^^^^^^^^^^^^^^^^^^^^
  File "C:\robot_work\.venv\Lib\site-packages\django\views\decorators\csrf.py", line 54, in wrapped_view
    return view_func(*args, **kwargs)
           ^^^^^^^^^^^^^^^^^^^^^^^^^^
  File "C:\robot_work\.venv\Lib\site-packages\django\views\generic\base.py", line 71, in view
    return self.dispatch(request, *args, **kwargs)
           ^^^^^^^^^^^^^^^^^^^^^^^^^^^^^^^^^^^^^^^
  File "C:\robot_work\.venv\Lib\site-packages\rest_framework\views.py", line 509, in dispatch
    response = self.handle_exception(exc)
               ^^^^^^^^^^^^^^^^^^^^^^^^^^
  File "C:\robot_work\.venv\Lib\site-packages\rest_framework\views.py", line 469, in handle_exception
    self.raise_uncaught_exception(exc)
  File "C:\robot_work\.venv\Lib\site-packages\rest_framework\views.py", line 480, in raise_uncaught_exception
    raise exc
  File "C:\robot_work\.venv\Lib\site-packages\rest_framework\views.py", line 506, in dispatch
    response = handler(request, *args, **kwargs)
               ^^^^^^^^^^^^^^^^^^^^^^^^^^^^^^^^^
  File "C:\robot_work\.venv\Lib\site-packages\rest_framework\decorators.py", line 50, in handler
    return func(*args, **kwargs)
           ^^^^^^^^^^^^^^^^^^^^^
  File "C:\robot_work\.venv\Lib\site-packages\gerapy\server\core\views.py", line 73, in index_status
    files = os.listdir(path)
            ^^^^^^^^^^^^^^^^
FileNotFoundError: [WinError 3] 系统找不到指定的路径。: 'C:\\robot_work\\projects'
ERROR - 2024-11-10 21:57:39,578 - process: 6576 - utils.py - gerapy.server.core.utils - 564 - utils - HTTPConnectionPool(host='192.168.0.141', port=6800): Max retries exceeded with url: / (Caused by ConnectTimeoutError(<urllib3.connection.HTTPConnection object at 0x000001E442A200B0>, 'Connection to 192.168.0.141 timed out. (connect timeout=3)'))
Traceback (most recent call last):
  File "C:\robot_work\.venv\Lib\site-packages\urllib3\connection.py", line 174, in _new_conn
    conn = connection.create_connection(
           ^^^^^^^^^^^^^^^^^^^^^^^^^^^^^
  File "C:\robot_work\.venv\Lib\site-packages\urllib3\util\connection.py", line 95, in create_connection
    raise err
  File "C:\robot_work\.venv\Lib\site-packages\urllib3\util\connection.py", line 85, in create_connection
    sock.connect(sa)
TimeoutError: timed out

During handling of the above exception, another exception occurred:

Traceback (most recent call last):
  File "C:\robot_work\.venv\Lib\site-packages\urllib3\connectionpool.py", line 716, in urlopen
    httplib_response = self._make_request(
                       ^^^^^^^^^^^^^^^^^^^
  File "C:\robot_work\.venv\Lib\site-packages\urllib3\connectionpool.py", line 416, in _make_request
    conn.request(method, url, **httplib_request_kw)
  File "C:\robot_work\.venv\Lib\site-packages\urllib3\connection.py", line 244, in request
    super(HTTPConnection, self).request(method, url, body=body, headers=headers)
  File "C:\Users\张洛\AppData\Local\Programs\Python\Python312\Lib\http\client.py", line 1319, in request
    self._send_request(method, url, body, headers, encode_chunked)
  File "C:\Users\张洛\AppData\Local\Programs\Python\Python312\Lib\http\client.py", line 1365, in _send_request
    self.endheaders(body, encode_chunked=encode_chunked)
  File "C:\Users\张洛\AppData\Local\Programs\Python\Python312\Lib\http\client.py", line 1314, in endheaders
    self._send_output(message_body, encode_chunked=encode_chunked)
  File "C:\Users\张洛\AppData\Local\Programs\Python\Python312\Lib\http\client.py", line 1074, in _send_output
    self.send(msg)
  File "C:\Users\张洛\AppData\Local\Programs\Python\Python312\Lib\http\client.py", line 1018, in send
    self.connect()
  File "C:\robot_work\.venv\Lib\site-packages\urllib3\connection.py", line 205, in connect
    conn = self._new_conn()
           ^^^^^^^^^^^^^^^^
  File "C:\robot_work\.venv\Lib\site-packages\urllib3\connection.py", line 179, in _new_conn
    raise ConnectTimeoutError(
urllib3.exceptions.ConnectTimeoutError: (<urllib3.connection.HTTPConnection object at 0x000001E442A200B0>, 'Connection to 192.168.0.141 timed out. (connect timeout=3)')

During handling of the above exception, another exception occurred:

Traceback (most recent call last):
  File "C:\robot_work\.venv\Lib\site-packages\requests\adapters.py", line 667, in send
    resp = conn.urlopen(
           ^^^^^^^^^^^^^
  File "C:\robot_work\.venv\Lib\site-packages\urllib3\connectionpool.py", line 802, in urlopen
    retries = retries.increment(
              ^^^^^^^^^^^^^^^^^^
  File "C:\robot_work\.venv\Lib\site-packages\urllib3\util\retry.py", line 594, in increment
    raise MaxRetryError(_pool, url, error or ResponseError(cause))
urllib3.exceptions.MaxRetryError: HTTPConnectionPool(host='192.168.0.141', port=6800): Max retries exceeded with url: / (Caused by ConnectTimeoutError(<urllib3.connection.HTTPConnection object at 0x000001E442A200B0>, 'Connection to 192.168.0.141 timed out. (connect timeout=3)'))

During handling of the above exception, another exception occurred:

Traceback (most recent call last):
  File "C:\robot_work\.venv\Lib\site-packages\gerapy\server\core\utils.py", line 562, in wrapper
    result = func(*args, **kwargs)
             ^^^^^^^^^^^^^^^^^^^^^
  File "C:\robot_work\.venv\Lib\site-packages\django\views\decorators\csrf.py", line 54, in wrapped_view
    return view_func(*args, **kwargs)
           ^^^^^^^^^^^^^^^^^^^^^^^^^^
  File "C:\robot_work\.venv\Lib\site-packages\django\views\generic\base.py", line 71, in view
    return self.dispatch(request, *args, **kwargs)
           ^^^^^^^^^^^^^^^^^^^^^^^^^^^^^^^^^^^^^^^
  File "C:\robot_work\.venv\Lib\site-packages\rest_framework\views.py", line 509, in dispatch
    response = self.handle_exception(exc)
               ^^^^^^^^^^^^^^^^^^^^^^^^^^
  File "C:\robot_work\.venv\Lib\site-packages\rest_framework\views.py", line 469, in handle_exception
    self.raise_uncaught_exception(exc)
  File "C:\robot_work\.venv\Lib\site-packages\rest_framework\views.py", line 480, in raise_uncaught_exception
    raise exc
  File "C:\robot_work\.venv\Lib\site-packages\rest_framework\views.py", line 506, in dispatch
    response = handler(request, *args, **kwargs)
               ^^^^^^^^^^^^^^^^^^^^^^^^^^^^^^^^^
  File "C:\robot_work\.venv\Lib\site-packages\rest_framework\decorators.py", line 50, in handler
    return func(*args, **kwargs)
           ^^^^^^^^^^^^^^^^^^^^^
  File "C:\robot_work\.venv\Lib\site-packages\gerapy\server\core\views.py", line 120, in client_status
    requests.get(scrapyd_url(client.ip, client.port), timeout=3)
  File "C:\robot_work\.venv\Lib\site-packages\requests\api.py", line 73, in get
    return request("get", url, params=params, **kwargs)
           ^^^^^^^^^^^^^^^^^^^^^^^^^^^^^^^^^^^^^^^^^^^^
  File "C:\robot_work\.venv\Lib\site-packages\requests\api.py", line 59, in request
    return session.request(method=method, url=url, **kwargs)
           ^^^^^^^^^^^^^^^^^^^^^^^^^^^^^^^^^^^^^^^^^^^^^^^^^
  File "C:\robot_work\.venv\Lib\site-packages\requests\sessions.py", line 589, in request
    resp = self.send(prep, **send_kwargs)
           ^^^^^^^^^^^^^^^^^^^^^^^^^^^^^^
  File "C:\robot_work\.venv\Lib\site-packages\requests\sessions.py", line 703, in send
    r = adapter.send(request, **kwargs)
        ^^^^^^^^^^^^^^^^^^^^^^^^^^^^^^^
  File "C:\robot_work\.venv\Lib\site-packages\requests\adapters.py", line 688, in send
    raise ConnectTimeout(e, request=request)
requests.exceptions.ConnectTimeout: HTTPConnectionPool(host='192.168.0.141', port=6800): Max retries exceeded with url: / (Caused by ConnectTimeoutError(<urllib3.connection.HTTPConnection object at 0x000001E442A200B0>, 'Connection to 192.168.0.141 timed out. (connect timeout=3)'))
